Workbook
Name Check6: Aneesh!$C$27
Name Check6: 'Leave Form'!$C$27

Sheet UG Leave 
B2: Month | D2: 45962 | F2: Present | G2: Absent | H2: Half day | I2: Training | J2: Casual Leave | K2: Casual Balance | L2: Sick Leave | M2: Balance | N2: Annual Leave | O2: Balance | P2: Maternity Leave | Q2: Balance | R2: Paternity Leave | S2: Balance | T2: Work Feom Home | U2: National Holiday | V2: Total
B3: Employee Name | D3: ID | F3: P | G3: AB | H3: HD | I3: TR | J3: CL | K3: CL | L3: SL | M3: SL | N3: AL | O3: AL | P3: ML | Q3: ML | R3: PL | S3: PL | T3: WH | U3: NH
J4: 4 | L4: 30 | N4: 21 | P4: 60 | R4: 4 | W4: Designation | X4: Date of Birth | Y4: Joining Date | Z4: Contact Number | AA4: E Mail
B5: Nyinimuntu Angela | C5: F | D5: VUEMP001 | F5: =COUNTIF(D5:D5,"P") -> 0 | J5: ='UG December 2026'!AN4+'UG November 2026'!AN4+'UG October 2026'!AN4+'UG September 2026'!AN4+'UG August 2026'!AN4+'UG July 2026'!AN4+'UG June 2026'!AN4+'UG May 2026'!AN4+'UG April 2026'!AN4+'UG March 2026'!AN4+'UG February 2026'!AN4+'UG January 2026'!AN4 -> 0 | K5: =$J$4-J5 -> 4 | L5: ='UG December 2026'!AO4+'UG November 2026'!AO4+'UG October 2026'!AO4+'UG September 2026'!AO4+'UG August 2026'!AO4+'UG July 2026'!AO4+'UG June 2026'!AO4+'UG May 2026'!AO4+'UG April 2026'!AO4+'UG March 2026'!AO4+'UG February 2026'!AO4+'UG January 2026'!AO4 -> 3 | M5: =$L$4-L5 -> 27 | N5: ='UG December 2026'!AP4+'UG November 2026'!AP4+'UG October 2026'!AP4+'UG September 2026'!AP4+'UG August 2026'!AP4+'UG July 2026'!AP4+'UG June 2026'!AP4+'UG May 2026'!AP4+'UG April 2026'!AP4+'UG March 2026'!AP4+'UG February 2026'!AP4+'UG January 2026'!AP4 -> 1 | O5: =$N$4-N5 -> 20 | P5: ='UG December 2026'!AQ4+'UG November 2026'!AQ4+'UG October 2026'!AQ4+'UG September 2026'!AQ4+'UG August 2026'!AQ4+'UG July 2026'!AQ4+'UG June 2026'!AQ4+'UG May 2026'!AQ4+'UG April 2026'!AQ4+'UG March 2026'!AQ4+'UG February 2026'!AQ4+'UG January 2026'!AQ4 -> 47 | Q5: =IF(C5="F",$P$4-P5,0) -> 13 | R5: ='UG December 2026'!AR4+'UG November 2026'!AR4+'UG October 2026'!AR4+'UG September 2026'!AR4+'UG August 2026'!AR4+'UG July 2026'!AR4+'UG June 2026'!AR4+'UG May 2026'!AR4+'UG April 2026'!AR4+'UG March 2026'!AR4+'UG February 2026'!AR4+'UG January 2026'!AR4 -> 0 | S5: =IF(C5="M",$R$4-R5,0) -> 0 | W5: Sales Manager | X5: 24/10/1988 | Y5: 43405 | Z5: +256 773 004908 | AA5: angela.nyinimuntu@visionscientificafrica.com
B6: Joseph Opolot | C6: M | D6: VUEMP002 | F6: =COUNTIF(D6:D6,"P") -> 0 | J6: ='UG December 2026'!AN5+'UG November 2026'!AN5+'UG October 2026'!AN5+'UG September 2026'!AN5+'UG August 2026'!AN5+'UG July 2026'!AN5+'UG June 2026'!AN5+'UG May 2026'!AN5+'UG April 2026'!AN5+'UG March 2026'!AN5+'UG February 2026'!AN5+'UG January 2026'!AN5 -> 0 | K6: =$J$4-J6 -> 4 | L6: ='UG December 2026'!AO5+'UG November 2026'!AO5+'UG October 2026'!AO5+'UG September 2026'!AO5+'UG August 2026'!AO5+'UG July 2026'!AO5+'UG June 2026'!AO5+'UG May 2026'!AO5+'UG April 2026'!AO5+'UG March 2026'!AO5+'UG February 2026'!AO5+'UG January 2026'!AO5 -> 0 | M6: =$L$4-L6 -> 30 | N6: ='UG December 2026'!AP5+'UG November 2026'!AP5+'UG October 2026'!AP5+'UG September 2026'!AP5+'UG August 2026'!AP5+'UG July 2026'!AP5+'UG June 2026'!AP5+'UG May 2026'!AP5+'UG April 2026'!AP5+'UG March 2026'!AP5+'UG February 2026'!AP5+'UG January 2026'!AP5 -> 2 | O6: =$N$4-N6 -> 19 | P6: ='UG December 2026'!AQ5+'UG November 2026'!AQ5+'UG October 2026'!AQ5+'UG September 2026'!AQ5+'UG August 2026'!AQ5+'UG July 2026'!AQ5+'UG June 2026'!AQ5+'UG May 2026'!AQ5+'UG April 2026'!AQ5+'UG March 2026'!AQ5+'UG February 2026'!AQ5+'UG January 2026'!AQ5 -> 0 | Q6: =IF(C6="F",$P$4-P6,0) -> 0 | R6: ='UG December 2026'!AR5+'UG November 2026'!AR5+'UG October 2026'!AR5+'UG September 2026'!AR5+'UG August 2026'!AR5+'UG July 2026'!AR5+'UG June 2026'!AR5+'UG May 2026'!AR5+'UG April 2026'!AR5+'UG March 2026'!AR5+'UG February 2026'!AR5+'UG January 2026'!AR5 -> 0 | S6: =IF(C6="M",$R$4-R6,0) -> 4 | W6: Finance Manager | X6: 26/04/1977 | Y6: 42461 | Z6: +256 701 179851 | AA6: joseph.opolot@visionscientificafrica.com
B7: Moses Ikwara | C7: M | D7: VUEMP004 | F7: =COUNTIF(D7:D7,"P") -> 0 | J7: ='UG December 2026'!AN6+'UG November 2026'!AN6+'UG October 2026'!AN6+'UG September 2026'!AN6+'UG August 2026'!AN6+'UG July 2026'!AN6+'UG June 2026'!AN6+'UG May 2026'!AN6+'UG April 2026'!AN6+'UG March 2026'!AN6+'UG February 2026'!AN6+'UG January 2026'!AN6 -> 0 | K7: =$J$4-J7 -> 4 | L7: ='UG December 2026'!AO6+'UG November 2026'!AO6+'UG October 2026'!AO6+'UG September 2026'!AO6+'UG August 2026'!AO6+'UG July 2026'!AO6+'UG June 2026'!AO6+'UG May 2026'!AO6+'UG April 2026'!AO6+'UG March 2026'!AO6+'UG February 2026'!AO6+'UG January 2026'!AO6 -> 0 | M7: =$L$4-L7 -> 30 | N7: ='UG December 2026'!AP6+'UG November 2026'!AP6+'UG October 2026'!AP6+'UG September 2026'!AP6+'UG August 2026'!AP6+'UG July 2026'!AP6+'UG June 2026'!AP6+'UG May 2026'!AP6+'UG April 2026'!AP6+'UG March 2026'!AP6+'UG February 2026'!AP6+'UG January 2026'!AP6 -> 6 | O7: =$N$4-N7 -> 15 | P7: ='UG December 2026'!AQ6+'UG November 2026'!AQ6+'UG October 2026'!AQ6+'UG September 2026'!AQ6+'UG August 2026'!AQ6+'UG July 2026'!AQ6+'UG June 2026'!AQ6+'UG May 2026'!AQ6+'UG April 2026'!AQ6+'UG March 2026'!AQ6+'UG February 2026'!AQ6+'UG January 2026'!AQ6 -> 0 | Q7: =IF(C7="F",$P$4-P7,0) -> 0 | R7: ='UG December 2026'!AR6+'UG November 2026'!AR6+'UG October 2026'!AR6+'UG September 2026'!AR6+'UG August 2026'!AR6+'UG July 2026'!AR6+'UG June 2026'!AR6+'UG May 2026'!AR6+'UG April 2026'!AR6+'UG March 2026'!AR6+'UG February 2026'!AR6+'UG January 2026'!AR6 -> 0 | S7: =IF(C7="M",$R$4-R7,0) -> 4 | W7: Ware House Executive | X7: 23/09/1977 | Y7: 42309 | Z7: +256 772 900196
B8: Hawa Sirikye | C8: F | D8: VUEMP005 | F8: =COUNTIF(D8:D8,"P") -> 0 | J8: ='UG December 2026'!AN7+'UG November 2026'!AN7+'UG October 2026'!AN7+'UG September 2026'!AN7+'UG August 2026'!AN7+'UG July 2026'!AN7+'UG June 2026'!AN7+'UG May 2026'!AN7+'UG April 2026'!AN7+'UG March 2026'!AN7+'UG February 2026'!AN7+'UG January 2026'!AN7 -> 0 | K8: =$J$4-J8 -> 4 | L8: ='UG December 2026'!AO7+'UG November 2026'!AO7+'UG October 2026'!AO7+'UG September 2026'!AO7+'UG August 2026'!AO7+'UG July 2026'!AO7+'UG June 2026'!AO7+'UG May 2026'!AO7+'UG April 2026'!AO7+'UG March 2026'!AO7+'UG February 2026'!AO7+'UG January 2026'!AO7 -> 1 | M8: =$L$4-L8 -> 29 | N8: ='UG December 2026'!AP7+'UG November 2026'!AP7+'UG October 2026'!AP7+'UG September 2026'!AP7+'UG August 2026'!AP7+'UG July 2026'!AP7+'UG June 2026'!AP7+'UG May 2026'!AP7+'UG April 2026'!AP7+'UG March 2026'!AP7+'UG February 2026'!AP7+'UG January 2026'!AP7 -> 1 | O8: =$N$4-N8 -> 20 | P8: ='UG December 2026'!AQ7+'UG November 2026'!AQ7+'UG October 2026'!AQ7+'UG September 2026'!AQ7+'UG August 2026'!AQ7+'UG July 2026'!AQ7+'UG June 2026'!AQ7+'UG May 2026'!AQ7+'UG April 2026'!AQ7+'UG March 2026'!AQ7+'UG February 2026'!AQ7+'UG January 2026'!AQ7 -> 0 | Q8: =IF(C8="F",$P$4-P8,0) -> 60 | R8: ='UG December 2026'!AR7+'UG November 2026'!AR7+'UG October 2026'!AR7+'UG September 2026'!AR7+'UG August 2026'!AR7+'UG July 2026'!AR7+'UG June 2026'!AR7+'UG May 2026'!AR7+'UG April 2026'!AR7+'UG March 2026'!AR7+'UG February 2026'!AR7+'UG January 2026'!AR7 -> 0 | S8: =IF(C8="M",$R$4-R8,0) -> 0 | W8: Front Office Executive | X8: 30/04/1991 | Y8: 43132 | Z8: +256 755 229943 | AA8: hawa.nasinza@visionscientificafrica.com
B9: Aneesh Mathew | C9: M | D9: VUEMP008 | F9: =COUNTIF(D9:D9,"P") -> 0 | J9: ='UG December 2026'!AN8+'UG November 2026'!AN8+'UG October 2026'!AN8+'UG September 2026'!AN8+'UG August 2026'!AN8+'UG July 2026'!AN8+'UG June 2026'!AN8+'UG May 2026'!AN8+'UG April 2026'!AN8+'UG March 2026'!AN8+'UG February 2026'!AN8+'UG January 2026'!AN8 -> 0 | K9: =$J$4-J9 -> 4 | L9: ='UG December 2026'!AO8+'UG November 2026'!AO8+'UG October 2026'!AO8+'UG September 2026'!AO8+'UG August 2026'!AO8+'UG July 2026'!AO8+'UG June 2026'!AO8+'UG May 2026'!AO8+'UG April 2026'!AO8+'UG March 2026'!AO8+'UG February 2026'!AO8+'UG January 2026'!AO8 -> 0 | M9: =$L$4-L9 -> 30 | N9: ='UG December 2026'!AP8+'UG November 2026'!AP8+'UG October 2026'!AP8+'UG September 2026'!AP8+'UG August 2026'!AP8+'UG July 2026'!AP8+'UG June 2026'!AP8+'UG May 2026'!AP8+'UG April 2026'!AP8+'UG March 2026'!AP8+'UG February 2026'!AP8+'UG January 2026'!AP8 -> 0 | O9: =$N$4-N9 -> 21 | P9: ='UG December 2026'!AQ8+'UG November 2026'!AQ8+'UG October 2026'!AQ8+'UG September 2026'!AQ8+'UG August 2026'!AQ8+'UG July 2026'!AQ8+'UG June 2026'!AQ8+'UG May 2026'!AQ8+'UG April 2026'!AQ8+'UG March 2026'!AQ8+'UG February 2026'!AQ8+'UG January 2026'!AQ8 -> 0 | Q9: =IF(C9="F",$P$4-P9,0) -> 0 | R9: ='UG December 2026'!AR8+'UG November 2026'!AR8+'UG October 2026'!AR8+'UG September 2026'!AR8+'UG August 2026'!AR8+'UG July 2026'!AR8+'UG June 2026'!AR8+'UG May 2026'!AR8+'UG April 2026'!AR8+'UG March 2026'!AR8+'UG February 2026'!AR8+'UG January 2026'!AR8 -> 0 | S9: =IF(C9="M",$R$4-R9,0) -> 4 | W9: Country Manager | X9: 07/08/1984 | Y9: 44317 | Z9: +256 709167800 | AA9: aneesh.mathew@visionscientificafrica.com
B10: Atim Bernadatte | C10: F | D10: VUEMP009 | F10: =COUNTIF(D10:D10,"P") -> 0 | J10: ='UG December 2026'!AN9+'UG November 2026'!AN9+'UG October 2026'!AN9+'UG September 2026'!AN9+'UG August 2026'!AN9+'UG July 2026'!AN9+'UG June 2026'!AN9+'UG May 2026'!AN9+'UG April 2026'!AN9+'UG March 2026'!AN9+'UG February 2026'!AN9+'UG January 2026'!AN9 -> 0 | K10: =$J$4-J10 -> 4 | L10: ='UG December 2026'!AO9+'UG November 2026'!AO9+'UG October 2026'!AO9+'UG September 2026'!AO9+'UG August 2026'!AO9+'UG July 2026'!AO9+'UG June 2026'!AO9+'UG May 2026'!AO9+'UG April 2026'!AO9+'UG March 2026'!AO9+'UG February 2026'!AO9+'UG January 2026'!AO9 -> 2 | M10: =$L$4-L10 -> 28 | N10: ='UG December 2026'!AP9+'UG November 2026'!AP9+'UG October 2026'!AP9+'UG September 2026'!AP9+'UG August 2026'!AP9+'UG July 2026'!AP9+'UG June 2026'!AP9+'UG May 2026'!AP9+'UG April 2026'!AP9+'UG March 2026'!AP9+'UG February 2026'!AP9+'UG January 2026'!AP9 -> 1 | O10: =$N$4-N10 -> 20 | P10: ='UG December 2026'!AQ9+'UG November 2026'!AQ9+'UG October 2026'!AQ9+'UG September 2026'!AQ9+'UG August 2026'!AQ9+'UG July 2026'!AQ9+'UG June 2026'!AQ9+'UG May 2026'!AQ9+'UG April 2026'!AQ9+'UG March 2026'!AQ9+'UG February 2026'!AQ9+'UG January 2026'!AQ9 -> 0 | Q10: =IF(C10="F",$P$4-P10,0) -> 60 | R10: ='UG December 2026'!AR9+'UG November 2026'!AR9+'UG October 2026'!AR9+'UG September 2026'!AR9+'UG August 2026'!AR9+'UG July 2026'!AR9+'UG June 2026'!AR9+'UG May 2026'!AR9+'UG April 2026'!AR9+'UG March 2026'!AR9+'UG February 2026'!AR9+'UG January 2026'!AR9 -> 0 | S10: =IF(C10="M",$R$4-R10,0) -> 0 | W10: Office Assistant | X10: 01/04/1996 | Y10: 44348 | Z10: +256 786 135912
B11: Kawunde Paul | C11: M | D11: VUEMP011 | F11: =COUNTIF(D11:D11,"P") -> 0 | J11: ='UG December 2026'!AN10+'UG November 2026'!AN10+'UG October 2026'!AN10+'UG September 2026'!AN10+'UG August 2026'!AN10+'UG July 2026'!AN10+'UG June 2026'!AN10+'UG May 2026'!AN10+'UG April 2026'!AN10+'UG March 2026'!AN10+'UG February 2026'!AN10+'UG January 2026'!AN10 -> 0 | K11: =$J$4-J11 -> 4 | L11: ='UG December 2026'!AO10+'UG November 2026'!AO10+'UG October 2026'!AO10+'UG September 2026'!AO10+'UG August 2026'!AO10+'UG July 2026'!AO10+'UG June 2026'!AO10+'UG May 2026'!AO10+'UG April 2026'!AO10+'UG March 2026'!AO10+'UG February 2026'!AO10+'UG January 2026'!AO10 -> 0 | M11: =$L$4-L11 -> 30 | N11: ='UG December 2026'!AP10+'UG November 2026'!AP10+'UG October 2026'!AP10+'UG September 2026'!AP10+'UG August 2026'!AP10+'UG July 2026'!AP10+'UG June 2026'!AP10+'UG May 2026'!AP10+'UG April 2026'!AP10+'UG March 2026'!AP10+'UG February 2026'!AP10+'UG January 2026'!AP10 -> 1 | O11: =$N$4-N11 -> 20 | P11: ='UG December 2026'!AQ10+'UG November 2026'!AQ10+'UG October 2026'!AQ10+'UG September 2026'!AQ10+'UG August 2026'!AQ10+'UG July 2026'!AQ10+'UG June 2026'!AQ10+'UG May 2026'!AQ10+'UG April 2026'!AQ10+'UG March 2026'!AQ10+'UG February 2026'!AQ10+'UG January 2026'!AQ10 -> 0 | Q11: =IF(C11="F",$P$4-P11,0) -> 0 | R11: ='UG December 2026'!AR10+'UG November 2026'!AR10+'UG October 2026'!AR10+'UG September 2026'!AR10+'UG August 2026'!AR10+'UG July 2026'!AR10+'UG June 2026'!AR10+'UG May 2026'!AR10+'UG April 2026'!AR10+'UG March 2026'!AR10+'UG February 2026'!AR10+'UG January 2026'!AR10 -> 0 | S11: =IF(C11="M",$R$4-R11,0) -> 4 | W11: Business Development Executive | X11: 29/12/1994 | Y11: 43862 | Z11: +256 780 610392 | AA11: paul.kawunde@visionscientificafrica.com
B12: Lubega Joel Brian | C12: M | D12: VUEMP015 | F12: =COUNTIF(D12:D12,"P") -> 0 | J12: ='UG December 2026'!AN11+'UG November 2026'!AN11+'UG October 2026'!AN11+'UG September 2026'!AN11+'UG August 2026'!AN11+'UG July 2026'!AN11+'UG June 2026'!AN11+'UG May 2026'!AN11+'UG April 2026'!AN11+'UG March 2026'!AN11+'UG February 2026'!AN11+'UG January 2026'!AN11 -> 0 | K12: =$J$4-J12 -> 4 | L12: ='UG December 2026'!AO11+'UG November 2026'!AO11+'UG October 2026'!AO11+'UG September 2026'!AO11+'UG August 2026'!AO11+'UG July 2026'!AO11+'UG June 2026'!AO11+'UG May 2026'!AO11+'UG April 2026'!AO11+'UG March 2026'!AO11+'UG February 2026'!AO11+'UG January 2026'!AO11 -> 1 | M12: =$L$4-L12 -> 29 | N12: ='UG December 2026'!AP11+'UG November 2026'!AP11+'UG October 2026'!AP11+'UG September 2026'!AP11+'UG August 2026'!AP11+'UG July 2026'!AP11+'UG June 2026'!AP11+'UG May 2026'!AP11+'UG April 2026'!AP11+'UG March 2026'!AP11+'UG February 2026'!AP11+'UG January 2026'!AP11 -> 1 | O12: =$N$4-N12 -> 20 | P12: ='UG December 2026'!AQ11+'UG November 2026'!AQ11+'UG October 2026'!AQ11+'UG September 2026'!AQ11+'UG August 2026'!AQ11+'UG July 2026'!AQ11+'UG June 2026'!AQ11+'UG May 2026'!AQ11+'UG April 2026'!AQ11+'UG March 2026'!AQ11+'UG February 2026'!AQ11+'UG January 2026'!AQ11 -> 0 | Q12: =IF(C12="F",$P$4-P12,0) -> 0 | R12: ='UG December 2026'!AR11+'UG November 2026'!AR11+'UG October 2026'!AR11+'UG September 2026'!AR11+'UG August 2026'!AR11+'UG July 2026'!AR11+'UG June 2026'!AR11+'UG May 2026'!AR11+'UG April 2026'!AR11+'UG March 2026'!AR11+'UG February 2026'!AR11+'UG January 2026'!AR11 -> 0 | S12: =IF(C12="M",$R$4-R12,0) -> 4 | W12: Business Development Executive | X12: 04/12/1988 | Y12: 45108 | Z12: +256 784 042269 | AA12: brian.lubega@visionscientificafrica.com
B13: Joseph Wetaka Wandega | C13: M | D13: VUEMP017 | F13: =COUNTIF(D13:D13,"P") -> 0 | J13: ='UG December 2026'!AN12+'UG November 2026'!AN12+'UG October 2026'!AN12+'UG September 2026'!AN12+'UG August 2026'!AN12+'UG July 2026'!AN12+'UG June 2026'!AN12+'UG May 2026'!AN12+'UG April 2026'!AN12+'UG March 2026'!AN12+'UG February 2026'!AN12+'UG January 2026'!AN12 -> 0 | K13: =$J$4-J13 -> 4 | L13: ='UG December 2026'!AO12+'UG November 2026'!AO12+'UG October 2026'!AO12+'UG September 2026'!AO12+'UG August 2026'!AO12+'UG July 2026'!AO12+'UG June 2026'!AO12+'UG May 2026'!AO12+'UG April 2026'!AO12+'UG March 2026'!AO12+'UG February 2026'!AO12+'UG January 2026'!AO12 -> 0 | M13: =$L$4-L13 -> 30 | N13: ='UG December 2026'!AP12+'UG November 2026'!AP12+'UG October 2026'!AP12+'UG September 2026'!AP12+'UG August 2026'!AP12+'UG July 2026'!AP12+'UG June 2026'!AP12+'UG May 2026'!AP12+'UG April 2026'!AP12+'UG March 2026'!AP12+'UG February 2026'!AP12+'UG January 2026'!AP12 -> 0 | O13: =$N$4-N13 -> 21 | P13: ='UG December 2026'!AQ12+'UG November 2026'!AQ12+'UG October 2026'!AQ12+'UG September 2026'!AQ12+'UG August 2026'!AQ12+'UG July 2026'!AQ12+'UG June 2026'!AQ12+'UG May 2026'!AQ12+'UG April 2026'!AQ12+'UG March 2026'!AQ12+'UG February 2026'!AQ12+'UG January 2026'!AQ12 -> 0 | Q13: =IF(C13="F",$P$4-P13,0) -> 0 | R13: ='UG December 2026'!AR12+'UG November 2026'!AR12+'UG October 2026'!AR12+'UG September 2026'!AR12+'UG August 2026'!AR12+'UG July 2026'!AR12+'UG June 2026'!AR12+'UG May 2026'!AR12+'UG April 2026'!AR12+'UG March 2026'!AR12+'UG February 2026'!AR12+'UG January 2026'!AR12 -> 0 | S13: =IF(C13="M",$R$4-R13,0) -> 4 | W13: Business Development Executive | X13: 19/02/1993 | Y13: 45544 | Z13: +256 771 456994 | AA13: joseph.wandega@visionscientificafrica.com
B14: Solomon Kiwunda | C14: M | D14: VUEMP018 | F14: =COUNTIF(D14:D14,"P") -> 0 | J14: ='UG December 2026'!AN13+'UG November 2026'!AN13+'UG October 2026'!AN13+'UG September 2026'!AN13+'UG August 2026'!AN13+'UG July 2026'!AN13+'UG June 2026'!AN13+'UG May 2026'!AN13+'UG April 2026'!AN13+'UG March 2026'!AN13+'UG February 2026'!AN13+'UG January 2026'!AN13 -> 0 | K14: =$J$4-J14 -> 4 | L14: ='UG December 2026'!AO13+'UG November 2026'!AO13+'UG October 2026'!AO13+'UG September 2026'!AO13+'UG August 2026'!AO13+'UG July 2026'!AO13+'UG June 2026'!AO13+'UG May 2026'!AO13+'UG April 2026'!AO13+'UG March 2026'!AO13+'UG February 2026'!AO13+'UG January 2026'!AO13 -> 0 | M14: =$L$4-L14 -> 30 | N14: ='UG December 2026'!AP13+'UG November 2026'!AP13+'UG October 2026'!AP13+'UG September 2026'!AP13+'UG August 2026'!AP13+'UG July 2026'!AP13+'UG June 2026'!AP13+'UG May 2026'!AP13+'UG April 2026'!AP13+'UG March 2026'!AP13+'UG February 2026'!AP13+'UG January 2026'!AP13 -> 1 | O14: =$N$4-N14 -> 20 | P14: ='UG December 2026'!AQ13+'UG November 2026'!AQ13+'UG October 2026'!AQ13+'UG September 2026'!AQ13+'UG August 2026'!AQ13+'UG July 2026'!AQ13+'UG June 2026'!AQ13+'UG May 2026'!AQ13+'UG April 2026'!AQ13+'UG March 2026'!AQ13+'UG February 2026'!AQ13+'UG January 2026'!AQ13 -> 0 | Q14: =IF(C14="F",$P$4-P14,0) -> 0 | R14: ='UG December 2026'!AR13+'UG November 2026'!AR13+'UG October 2026'!AR13+'UG September 2026'!AR13+'UG August 2026'!AR13+'UG July 2026'!AR13+'UG June 2026'!AR13+'UG May 2026'!AR13+'UG April 2026'!AR13+'UG March 2026'!AR13+'UG February 2026'!AR13+'UG January 2026'!AR13 -> 0 | S14: =IF(C14="M",$R$4-R14,0) -> 4 | W14: Business Development Executive | X14: 26/07/1996 | Y14: 45663 | Z14: +256 770 774150 | AA14: solomon.kiwunda@visionscientificafrica.com

Sheet UG December 2026
B2: Month | C2: 46357 | D2: 45992 | E2: 45993 | F2: 45994 | G2: 45995 | H2: 45996 | I2: 45997 | J2: 45998 | K2: 45999 | L2: 46000 | M2: 46001 | N2: 46002 | O2: 46003 | P2: 46004 | Q2: 46005 | R2: 46006 | S2: 46007 | T2: 46008 | U2: 46009 | V2: 46010 | W2: 46011 | X2: 46012 | Y2: 46013 | Z2: 46014 | AA2: 46015 | AB2: 46016 | AC2: 46017 | AD2: 46018 | AE2: 46019 | AF2: 46020 | AG2: 46021 | AH2: 46022 | AJ2: Present | AK2: Absent | AL2: Half day | AM2: Training | AN2: Casual Leave | AO2: Sick Leave | AP2: Annual Leave | AQ2: Maternity Leave | AR2: Paternity Leave | AS2: Work Feom Home | AT2: National Holiday | AU2: Total
B3: Employee Name | C3: ID | D3: Tue | E3: Wed | F3: Thu | G3: Fri | H3: Sat | I3: Sun | J3: Mon | K3: Tue | L3: Wed | M3: Thu | N3: Fri | O3: Sat | P3: Sun | Q3: Mon | R3: Tue | S3: Wed | T3: Thu | U3: Fri | V3: Sat | W3: Sun | X3: Mon | Y3: Tue | Z3: Wed | AA3: Thu | AB3: Fri | AC3: Sat | AD3: Sun | AE3: Mon | AF3: Tue | AG3: Wed | AJ3: P | AK3: AB | AL3: HD | AM3: TR | AN3: CL | AO3: SL | AP3: AL | AQ3: ML | AR3: PL | AS3: WH | AT3: NH
B4: Nyinimuntu Angela | C4: VUEMP001 | AJ4: =COUNTIF(C4:AI4,"P") -> 0 | AK4: =COUNTIF(D4:AI4,"A") -> 0 | AL4: =COUNTIF(D4:AI4,"H") -> 0 | AM4: =COUNTIF(D4:AI4,"TR") -> 0 | AN4: =COUNTIF(D4:AI4,"CL") -> 0 | AO4: =COUNTIF(D4:AI4,"SL") -> 0 | AP4: =COUNTIF(D4:AI4,"AL") -> 0 | AQ4: =COUNTIF(D4:AI4,"ML") -> 0 | AR4: =COUNTIF(D4:AI4,"PL") -> 0 | AS4: =COUNTIF(D4:AI4,"WFH") -> 0 | AT4: =COUNTIF(D4:AI4,"NH") -> 0 | AU4: =SUM(AJ4:AT4) -> 0
B5: Joseph Opolot | C5: VUEMP002 | AJ5: =COUNTIF(C5:AI5,"P") -> 0 | AK5: =COUNTIF(D5:AI5,"A") -> 0 | AL5: =COUNTIF(D5:AI5,"H") -> 0 | AM5: =COUNTIF(D5:AI5,"TR") -> 0 | AN5: =COUNTIF(D5:AI5,"CL") -> 0 | AO5: =COUNTIF(D5:AI5,"SL") -> 0 | AP5: =COUNTIF(D5:AI5,"AL") -> 0 | AQ5: =COUNTIF(D5:AI5,"ML") -> 0 | AR5: =COUNTIF(D5:AI5,"PL") -> 0 | AS5: =COUNTIF(D5:AI5,"WFH") -> 0 | AT5: =COUNTIF(D5:AI5,"NH") -> 0 | AU5: =SUM(AJ5:AT5) -> 0
B6: Moses Ikwara | C6: VUEMP004 | AJ6: =COUNTIF(C6:AI6,"P") -> 0 | AK6: =COUNTIF(D6:AI6,"A") -> 0 | AL6: =COUNTIF(D6:AI6,"H") -> 0 | AM6: =COUNTIF(D6:AI6,"TR") -> 0 | AN6: =COUNTIF(D6:AI6,"CL") -> 0 | AO6: =COUNTIF(D6:AI6,"SL") -> 0 | AP6: =COUNTIF(D6:AI6,"AL") -> 0 | AQ6: =COUNTIF(D6:AI6,"ML") -> 0 | AR6: =COUNTIF(D6:AI6,"PL") -> 0 | AS6: =COUNTIF(D6:AI6,"WFH") -> 0 | AT6: =COUNTIF(D6:AI6,"NH") -> 0 | AU6: =SUM(AJ6:AT6) -> 0
B7: Hawa Sirikye | C7: VUEMP005 | AJ7: =COUNTIF(C7:AI7,"P") -> 0 | AK7: =COUNTIF(D7:AI7,"A") -> 0 | AL7: =COUNTIF(D7:AI7,"H") -> 0 | AM7: =COUNTIF(D7:AI7,"TR") -> 0 | AN7: =COUNTIF(D7:AI7,"CL") -> 0 | AO7: =COUNTIF(D7:AI7,"SL") -> 0 | AP7: =COUNTIF(D7:AI7,"AL") -> 0 | AQ7: =COUNTIF(D7:AI7,"ML") -> 0 | AR7: =COUNTIF(D7:AI7,"PL") -> 0 | AS7: =COUNTIF(D7:AI7,"WFH") -> 0 | AT7: =COUNTIF(D7:AI7,"NH") -> 0 | AU7: =SUM(AJ7:AT7) -> 0
B8: Aneesh Mathew | C8: VUEMP008 | AJ8: =COUNTIF(C8:AI8,"P") -> 0 | AK8: =COUNTIF(D8:AI8,"A") -> 0 | AL8: =COUNTIF(D8:AI8,"H") -> 0 | AM8: =COUNTIF(D8:AI8,"TR") -> 0 | AN8: =COUNTIF(D8:AI8,"CL") -> 0 | AO8: =COUNTIF(D8:AI8,"SL") -> 0 | AP8: =COUNTIF(D8:AI8,"AL") -> 0 | AQ8: =COUNTIF(D8:AI8,"ML") -> 0 | AR8: =COUNTIF(D8:AI8,"PL") -> 0 | AS8: =COUNTIF(D8:AI8,"WFH") -> 0 | AT8: =COUNTIF(D8:AI8,"NH") -> 0 | AU8: =SUM(AJ8:AT8) -> 0
B9: Atim Bernadatte | C9: VUEMP009 | AJ9: =COUNTIF(C9:AI9,"P") -> 0 | AK9: =COUNTIF(D9:AI9,"A") -> 0 | AL9: =COUNTIF(D9:AI9,"H") -> 0 | AM9: =COUNTIF(D9:AI9,"TR") -> 0 | AN9: =COUNTIF(D9:AI9,"CL") -> 0 | AO9: =COUNTIF(D9:AI9,"SL") -> 0 | AP9: =COUNTIF(D9:AI9,"AL") -> 0 | AQ9: =COUNTIF(D9:AI9,"ML") -> 0 | AR9: =COUNTIF(D9:AI9,"PL") -> 0 | AS9: =COUNTIF(D9:AI9,"WFH") -> 0 | AT9: =COUNTIF(D9:AI9,"NH") -> 0 | AU9: =SUM(AJ9:AT9) -> 0
B10: Kawunde Paul | C10: VUEMP011 | AJ10: =COUNTIF(C10:AI10,"P") -> 0 | AK10: =COUNTIF(D10:AI10,"A") -> 0 | AL10: =COUNTIF(D10:AI10,"H") -> 0 | AM10: =COUNTIF(D10:AI10,"TR") -> 0 | AN10: =COUNTIF(D10:AI10,"CL") -> 0 | AO10: =COUNTIF(D10:AI10,"SL") -> 0 | AP10: =COUNTIF(D10:AI10,"AL") -> 0 | AQ10: =COUNTIF(D10:AI10,"ML") -> 0 | AR10: =COUNTIF(D10:AI10,"PL") -> 0 | AS10: =COUNTIF(D10:AI10,"WFH") -> 0 | AT10: =COUNTIF(D10:AI10,"NH") -> 0 | AU10: =SUM(AJ10:AT10) -> 0
B11: Lubega Joel Brian | C11: VUEMP015 | AJ11: =COUNTIF(C11:AI11,"P") -> 0 | AK11: =COUNTIF(D11:AI11,"A") -> 0 | AL11: =COUNTIF(D11:AI11,"H") -> 0 | AM11: =COUNTIF(D11:AI11,"TR") -> 0 | AN11: =COUNTIF(D11:AI11,"CL") -> 0 | AO11: =COUNTIF(D11:AI11,"SL") -> 0 | AP11: =COUNTIF(D11:AI11,"AL") -> 0 | AQ11: =COUNTIF(D11:AI11,"ML") -> 0 | AR11: =COUNTIF(D11:AI11,"PL") -> 0 | AS11: =COUNTIF(D11:AI11,"WFH") -> 0 | AT11: =COUNTIF(D11:AI11,"NH") -> 0 | AU11: =SUM(AJ11:AT11) -> 0
B12: Joseph Wetaka Wandega | C12: VUEMP017 | AJ12: =COUNTIF(C12:AI12,"P") -> 0 | AK12: =COUNTIF(D12:AI12,"A") -> 0 | AL12: =COUNTIF(D12:AI12,"H") -> 0 | AM12: =COUNTIF(D12:AI12,"TR") -> 0 | AN12: =COUNTIF(D12:AI12,"CL") -> 0 | AO12: =COUNTIF(D12:AI12,"SL") -> 0 | AP12: =COUNTIF(D12:AI12,"AL") -> 0 | AQ12: =COUNTIF(D12:AI12,"ML") -> 0 | AR12: =COUNTIF(D12:AI12,"PL") -> 0 | AS12: =COUNTIF(D12:AI12,"WFH") -> 0 | AT12: =COUNTIF(D12:AI12,"NH") -> 0 | AU12: =SUM(AJ12:AT12) -> 0
B13: Solomon Kiwunda | C13: VUEMP018 | AJ13: =COUNTIF(C13:AI13,"P") -> 0 | AK13: =COUNTIF(D13:AI13,"A") -> 0 | AL13: =COUNTIF(D13:AI13,"H") -> 0 | AM13: =COUNTIF(D13:AI13,"TR") -> 0 | AN13: =COUNTIF(D13:AI13,"CL") -> 0 | AO13: =COUNTIF(D13:AI13,"SL") -> 0 | AP13: =COUNTIF(D13:AI13,"AL") -> 0 | AQ13: =COUNTIF(D13:AI13,"ML") -> 0 | AR13: =COUNTIF(D13:AI13,"PL") -> 0 | AS13: =COUNTIF(D13:AI13,"WFH") -> 0 | AT13: =COUNTIF(D13:AI13,"NH") -> 0 | AU13: =SUM(AJ13:AT13) -> 0

Sheet UG November 2026
B2: Month | C2: 46327 | D2: 45962 | E2: 45963 | F2: 45964 | G2: 45965 | H2: 45966 | I2: 45967 | J2: 45968 | K2: 45969 | L2: 45970 | M2: 45971 | N2: 45972 | O2: 45973 | P2: 45974 | Q2: 45975 | R2: 45976 | S2: 45977 | T2: 45978 | U2: 45979 | V2: 45980 | W2: 45981 | X2: 45982 | Y2: 45983 | Z2: 45984 | AA2: 45985 | AB2: 45986 | AC2: 45987 | AD2: 45988 | AE2: 45989 | AF2: 45990 | AG2: 45991 | AJ2: Present | AK2: Absent | AL2: Half day | AM2: Training | AN2: Casual Leave | AO2: Sick Leave | AP2: Annual Leave | AQ2: Maternity Leave | AR2: Paternity Leave | AS2: Work Feom Home | AT2: National Holiday | AU2: Total
B3: Employee Name | C3: ID | D3: Sun | E3: Mon | F3: Tue | G3: Wed | H3: Thu | I3: Fri | J3: Sat | K3: Sun | L3: Mon | M3: Tue | N3: Wed | O3: Thu | P3: Fri | Q3: Sat | R3: Sun | S3: Mon | T3: Tue | U3: Wed | V3: Thu | W3: Fri | X3: Sat | Y3: Sun | Z3: Mon | AA3: Tue | AB3: Wed | AC3: Thu | AD3: Fri | AE3: Sat | AF3: Sun | AG3: Mon | AJ3: P | AK3: AB | AL3: HD | AM3: TR | AN3: CL | AO3: SL | AP3: AL | AQ3: ML | AR3: PL | AS3: WH | AT3: NH
B4: Nyinimuntu Angela | C4: VUEMP001 | AJ4: =COUNTIF(C4:AI4,"P") -> 0 | AK4: =COUNTIF(D4:AI4,"A") -> 0 | AL4: =COUNTIF(D4:AI4,"H") -> 0 | AM4: =COUNTIF(D4:AI4,"TR") -> 0 | AN4: =COUNTIF(D4:AI4,"CL") -> 0 | AO4: =COUNTIF(D4:AI4,"SL") -> 0 | AP4: =COUNTIF(D4:AI4,"AL") -> 0 | AQ4: =COUNTIF(D4:AI4,"ML") -> 0 | AR4: =COUNTIF(D4:AI4,"PL") -> 0 | AS4: =COUNTIF(D4:AI4,"WFH") -> 0 | AT4: =COUNTIF(D4:AI4,"NH") -> 0 | AU4: =SUM(AJ4:AT4) -> 0
B5: Joseph Opolot | C5: VUEMP002 | AJ5: =COUNTIF(C5:AI5,"P") -> 0 | AK5: =COUNTIF(D5:AI5,"A") -> 0 | AL5: =COUNTIF(D5:AI5,"H") -> 0 | AM5: =COUNTIF(D5:AI5,"TR") -> 0 | AN5: =COUNTIF(D5:AI5,"CL") -> 0 | AO5: =COUNTIF(D5:AI5,"SL") -> 0 | AP5: =COUNTIF(D5:AI5,"AL") -> 0 | AQ5: =COUNTIF(D5:AI5,"ML") -> 0 | AR5: =COUNTIF(D5:AI5,"PL") -> 0 | AS5: =COUNTIF(D5:AI5,"WFH") -> 0 | AT5: =COUNTIF(D5:AI5,"NH") -> 0 | AU5: =SUM(AJ5:AT5) -> 0
B6: Moses Ikwara | C6: VUEMP004 | AJ6: =COUNTIF(C6:AI6,"P") -> 0 | AK6: =COUNTIF(D6:AI6,"A") -> 0 | AL6: =COUNTIF(D6:AI6,"H") -> 0 | AM6: =COUNTIF(D6:AI6,"TR") -> 0 | AN6: =COUNTIF(D6:AI6,"CL") -> 0 | AO6: =COUNTIF(D6:AI6,"SL") -> 0 | AP6: =COUNTIF(D6:AI6,"AL") -> 0 | AQ6: =COUNTIF(D6:AI6,"ML") -> 0 | AR6: =COUNTIF(D6:AI6,"PL") -> 0 | AS6: =COUNTIF(D6:AI6,"WFH") -> 0 | AT6: =COUNTIF(D6:AI6,"NH") -> 0 | AU6: =SUM(AJ6:AT6) -> 0
B7: Hawa Sirikye | C7: VUEMP005 | AJ7: =COUNTIF(C7:AI7,"P") -> 0 | AK7: =COUNTIF(D7:AI7,"A") -> 0 | AL7: =COUNTIF(D7:AI7,"H") -> 0 | AM7: =COUNTIF(D7:AI7,"TR") -> 0 | AN7: =COUNTIF(D7:AI7,"CL") -> 0 | AO7: =COUNTIF(D7:AI7,"SL") -> 0 | AP7: =COUNTIF(D7:AI7,"AL") -> 0 | AQ7: =COUNTIF(D7:AI7,"ML") -> 0 | AR7: =COUNTIF(D7:AI7,"PL") -> 0 | AS7: =COUNTIF(D7:AI7,"WFH") -> 0 | AT7: =COUNTIF(D7:AI7,"NH") -> 0 | AU7: =SUM(AJ7:AT7) -> 0
B8: Aneesh Mathew | C8: VUEMP008 | AJ8: =COUNTIF(C8:AI8,"P") -> 0 | AK8: =COUNTIF(D8:AI8,"A") -> 0 | AL8: =COUNTIF(D8:AI8,"H") -> 0 | AM8: =COUNTIF(D8:AI8,"TR") -> 0 | AN8: =COUNTIF(D8:AI8,"CL") -> 0 | AO8: =COUNTIF(D8:AI8,"SL") -> 0 | AP8: =COUNTIF(D8:AI8,"AL") -> 0 | AQ8: =COUNTIF(D8:AI8,"ML") -> 0 | AR8: =COUNTIF(D8:AI8,"PL") -> 0 | AS8: =COUNTIF(D8:AI8,"WFH") -> 0 | AT8: =COUNTIF(D8:AI8,"NH") -> 0 | AU8: =SUM(AJ8:AT8) -> 0
B9: Atim Bernadatte | C9: VUEMP009 | AJ9: =COUNTIF(C9:AI9,"P") -> 0 | AK9: =COUNTIF(D9:AI9,"A") -> 0 | AL9: =COUNTIF(D9:AI9,"H") -> 0 | AM9: =COUNTIF(D9:AI9,"TR") -> 0 | AN9: =COUNTIF(D9:AI9,"CL") -> 0 | AO9: =COUNTIF(D9:AI9,"SL") -> 0 | AP9: =COUNTIF(D9:AI9,"AL") -> 0 | AQ9: =COUNTIF(D9:AI9,"ML") -> 0 | AR9: =COUNTIF(D9:AI9,"PL") -> 0 | AS9: =COUNTIF(D9:AI9,"WFH") -> 0 | AT9: =COUNTIF(D9:AI9,"NH") -> 0 | AU9: =SUM(AJ9:AT9) -> 0
B10: Kawunde Paul | C10: VUEMP011 | AJ10: =COUNTIF(C10:AI10,"P") -> 0 | AK10: =COUNTIF(D10:AI10,"A") -> 0 | AL10: =COUNTIF(D10:AI10,"H") -> 0 | AM10: =COUNTIF(D10:AI10,"TR") -> 0 | AN10: =COUNTIF(D10:AI10,"CL") -> 0 | AO10: =COUNTIF(D10:AI10,"SL") -> 0 | AP10: =COUNTIF(D10:AI10,"AL") -> 0 | AQ10: =COUNTIF(D10:AI10,"ML") -> 0 | AR10: =COUNTIF(D10:AI10,"PL") -> 0 | AS10: =COUNTIF(D10:AI10,"WFH") -> 0 | AT10: =COUNTIF(D10:AI10,"NH") -> 0 | AU10: =SUM(AJ10:AT10) -> 0
B11: Lubega Joel Brian | C11: VUEMP015 | AJ11: =COUNTIF(C11:AI11,"P") -> 0 | AK11: =COUNTIF(D11:AI11,"A") -> 0 | AL11: =COUNTIF(D11:AI11,"H") -> 0 | AM11: =COUNTIF(D11:AI11,"TR") -> 0 | AN11: =COUNTIF(D11:AI11,"CL") -> 0 | AO11: =COUNTIF(D11:AI11,"SL") -> 0 | AP11: =COUNTIF(D11:AI11,"AL") -> 0 | AQ11: =COUNTIF(D11:AI11,"ML") -> 0 | AR11: =COUNTIF(D11:AI11,"PL") -> 0 | AS11: =COUNTIF(D11:AI11,"WFH") -> 0 | AT11: =COUNTIF(D11:AI11,"NH") -> 0 | AU11: =SUM(AJ11:AT11) -> 0
B12: Joseph Wetaka Wandega | C12: VUEMP017 | AJ12: =COUNTIF(C12:AI12,"P") -> 0 | AK12: =COUNTIF(D12:AI12,"A") -> 0 | AL12: =COUNTIF(D12:AI12,"H") -> 0 | AM12: =COUNTIF(D12:AI12,"TR") -> 0 | AN12: =COUNTIF(D12:AI12,"CL") -> 0 | AO12: =COUNTIF(D12:AI12,"SL") -> 0 | AP12: =COUNTIF(D12:AI12,"AL") -> 0 | AQ12: =COUNTIF(D12:AI12,"ML") -> 0 | AR12: =COUNTIF(D12:AI12,"PL") -> 0 | AS12: =COUNTIF(D12:AI12,"WFH") -> 0 | AT12: =COUNTIF(D12:AI12,"NH") -> 0 | AU12: =SUM(AJ12:AT12) -> 0
B13: Solomon Kiwunda | C13: VUEMP018 | AJ13: =COUNTIF(C13:AI13,"P") -> 0 | AK13: =COUNTIF(D13:AI13,"A") -> 0 | AL13: =COUNTIF(D13:AI13,"H") -> 0 | AM13: =COUNTIF(D13:AI13,"TR") -> 0 | AN13: =COUNTIF(D13:AI13,"CL") -> 0 | AO13: =COUNTIF(D13:AI13,"SL") -> 0 | AP13: =COUNTIF(D13:AI13,"AL") -> 0 | AQ13: =COUNTIF(D13:AI13,"ML") -> 0 | AR13: =COUNTIF(D13:AI13,"PL") -> 0 | AS13: =COUNTIF(D13:AI13,"WFH") -> 0 | AT13: =COUNTIF(D13:AI13,"NH") -> 0 | AU13: =SUM(AJ13:AT13) -> 0
B21: =1100000*8 -> 8800000

Sheet UG October 2026
B2: Month | C2: 46296 | D2: 45931 | E2: 45932 | F2: 45933 | G2: 45934 | H2: 45935 | I2: 45936 | J2: 45937 | K2: 45938 | L2: 45939 | M2: 45940 | N2: 45941 | O2: 45942 | P2: 45943 | Q2: 45944 | R2: 45945 | S2: 45946 | T2: 45947 | U2: 45948 | V2: 45949 | W2: 45950 | X2: 45951 | Y2: 45952 | Z2: 45953 | AA2: 45954 | AB2: 45955 | AC2: 45956 | AD2: 45957 | AE2: 45958 | AF2: 45959 | AG2: 45960 | AH2: 45961 | AJ2: Present | AK2: Absent | AL2: Half day | AM2: Training | AN2: Casual Leave | AO2: Sick Leave | AP2: Annual Leave | AQ2: Maternity Leave | AR2: Paternity Leave | AS2: Work Feom Home | AT2: National Holiday | AU2: Total
B3: Employee Name | C3: ID | D3: Thu | E3: Fri | F3: Sat | G3: Sun | H3: Mon | I3: Tue | J3: Wed | K3: Thu | L3: Fri | M3: Sat | N3: Sun | O3: Mon | P3: Tue | Q3: Wed | R3: Thu | S3: Fri | T3: Sat | U3: Sun | V3: Mon | W3: Tue | X3: Wed | Y3: Thu | Z3: Fri | AA3: Sat | AB3: Sun | AC3: Mon | AD3: Tue | AE3: Wed | AF3: Thu | AG3: Fri | AH3: Sat | AJ3: P | AK3: AB | AL3: HD | AM3: TR | AN3: CL | AO3: SL | AP3: AL | AQ3: ML | AR3: PL | AS3: WH | AT3: NH
B4: Nyinimuntu Angela | C4: VUEMP001 | AJ4: =COUNTIF(C4:AI4,"P") -> 0 | AK4: =COUNTIF(D4:AI4,"A") -> 0 | AL4: =COUNTIF(D4:AI4,"H") -> 0 | AM4: =COUNTIF(D4:AI4,"TR") -> 0 | AN4: =COUNTIF(D4:AI4,"CL") -> 0 | AO4: =COUNTIF(D4:AI4,"SL") -> 0 | AP4: =COUNTIF(D4:AI4,"AL") -> 0 | AQ4: =COUNTIF(D4:AI4,"ML") -> 0 | AR4: =COUNTIF(D4:AI4,"PL") -> 0 | AS4: =COUNTIF(D4:AI4,"WFH") -> 0 | AT4: =COUNTIF(D4:AI4,"NH") -> 0 | AU4: =SUM(AJ4:AT4) -> 0 | AW4: 17
B5: Joseph Opolot | C5: VUEMP002 | AJ5: =COUNTIF(C5:AI5,"P") -> 0 | AK5: =COUNTIF(D5:AI5,"A") -> 0 | AL5: =COUNTIF(D5:AI5,"H") -> 0 | AM5: =COUNTIF(D5:AI5,"TR") -> 0 | AN5: =COUNTIF(D5:AI5,"CL") -> 0 | AO5: =COUNTIF(D5:AI5,"SL") -> 0 | AP5: =COUNTIF(D5:AI5,"AL") -> 0 | AQ5: =COUNTIF(D5:AI5,"ML") -> 0 | AR5: =COUNTIF(D5:AI5,"PL") -> 0 | AS5: =COUNTIF(D5:AI5,"WFH") -> 0 | AT5: =COUNTIF(D5:AI5,"NH") -> 0 | AU5: =SUM(AJ5:AT5) -> 0 | AW5: 20
B6: Moses Ikwara | C6: VUEMP004 | AJ6: =COUNTIF(C6:AI6,"P") -> 0 | AK6: =COUNTIF(D6:AI6,"A") -> 0 | AL6: =COUNTIF(D6:AI6,"H") -> 0 | AM6: =COUNTIF(D6:AI6,"TR") -> 0 | AN6: =COUNTIF(D6:AI6,"CL") -> 0 | AO6: =COUNTIF(D6:AI6,"SL") -> 0 | AP6: =COUNTIF(D6:AI6,"AL") -> 0 | AQ6: =COUNTIF(D6:AI6,"ML") -> 0 | AR6: =COUNTIF(D6:AI6,"PL") -> 0 | AS6: =COUNTIF(D6:AI6,"WFH") -> 0 | AT6: =COUNTIF(D6:AI6,"NH") -> 0 | AU6: =SUM(AJ6:AT6) -> 0 | AW6: 22
B7: Hawa Sirikye | C7: VUEMP005 | AJ7: =COUNTIF(C7:AI7,"P") -> 0 | AK7: =COUNTIF(D7:AI7,"A") -> 0 | AL7: =COUNTIF(D7:AI7,"H") -> 0 | AM7: =COUNTIF(D7:AI7,"TR") -> 0 | AN7: =COUNTIF(D7:AI7,"CL") -> 0 | AO7: =COUNTIF(D7:AI7,"SL") -> 0 | AP7: =COUNTIF(D7:AI7,"AL") -> 0 | AQ7: =COUNTIF(D7:AI7,"ML") -> 0 | AR7: =COUNTIF(D7:AI7,"PL") -> 0 | AS7: =COUNTIF(D7:AI7,"WFH") -> 0 | AT7: =COUNTIF(D7:AI7,"NH") -> 0 | AU7: =SUM(AJ7:AT7) -> 0 | AW7: 18
B8: Aneesh Mathew | C8: VUEMP008 | AJ8: =COUNTIF(C8:AI8,"P") -> 0 | AK8: =COUNTIF(D8:AI8,"A") -> 0 | AL8: =COUNTIF(D8:AI8,"H") -> 0 | AM8: =COUNTIF(D8:AI8,"TR") -> 0 | AN8: =COUNTIF(D8:AI8,"CL") -> 0 | AO8: =COUNTIF(D8:AI8,"SL") -> 0 | AP8: =COUNTIF(D8:AI8,"AL") -> 0 | AQ8: =COUNTIF(D8:AI8,"ML") -> 0 | AR8: =COUNTIF(D8:AI8,"PL") -> 0 | AS8: =COUNTIF(D8:AI8,"WFH") -> 0 | AT8: =COUNTIF(D8:AI8,"NH") -> 0 | AU8: =SUM(AJ8:AT8) -> 0 | AW8: 22
B9: Atim Bernadatte | C9: VUEMP009 | AJ9: =COUNTIF(C9:AI9,"P") -> 0 | AK9: =COUNTIF(D9:AI9,"A") -> 0 | AL9: =COUNTIF(D9:AI9,"H") -> 0 | AM9: =COUNTIF(D9:AI9,"TR") -> 0 | AN9: =COUNTIF(D9:AI9,"CL") -> 0 | AO9: =COUNTIF(D9:AI9,"SL") -> 0 | AP9: =COUNTIF(D9:AI9,"AL") -> 0 | AQ9: =COUNTIF(D9:AI9,"ML") -> 0 | AR9: =COUNTIF(D9:AI9,"PL") -> 0 | AS9: =COUNTIF(D9:AI9,"WFH") -> 0 | AT9: =COUNTIF(D9:AI9,"NH") -> 0 | AU9: =SUM(AJ9:AT9) -> 0 | AW9: 22
B10: Kawunde Paul | C10: VUEMP011 | AJ10: =COUNTIF(C10:AI10,"P") -> 0 | AK10: =COUNTIF(D10:AI10,"A") -> 0 | AL10: =COUNTIF(D10:AI10,"H") -> 0 | AM10: =COUNTIF(D10:AI10,"TR") -> 0 | AN10: =COUNTIF(D10:AI10,"CL") -> 0 | AO10: =COUNTIF(D10:AI10,"SL") -> 0 | AP10: =COUNTIF(D10:AI10,"AL") -> 0 | AQ10: =COUNTIF(D10:AI10,"ML") -> 0 | AR10: =COUNTIF(D10:AI10,"PL") -> 0 | AS10: =COUNTIF(D10:AI10,"WFH") -> 0 | AT10: =COUNTIF(D10:AI10,"NH") -> 0 | AU10: =SUM(AJ10:AT10) -> 0 | AW10: 22
B11: Lubega Joel Brian | C11: VUEMP015 | AJ11: =COUNTIF(C11:AI11,"P") -> 0 | AK11: =COUNTIF(D11:AI11,"A") -> 0 | AL11: =COUNTIF(D11:AI11,"H") -> 0 | AM11: =COUNTIF(D11:AI11,"TR") -> 0 | AN11: =COUNTIF(D11:AI11,"CL") -> 0 | AO11: =COUNTIF(D11:AI11,"SL") -> 0 | AP11: =COUNTIF(D11:AI11,"AL") -> 0 | AQ11: =COUNTIF(D11:AI11,"ML") -> 0 | AR11: =COUNTIF(D11:AI11,"PL") -> 0 | AS11: =COUNTIF(D11:AI11,"WFH") -> 0 | AT11: =COUNTIF(D11:AI11,"NH") -> 0 | AU11: =SUM(AJ11:AT11) -> 0 | AW11: 22
B12: Joseph Wetaka Wandega | C12: VUEMP017 | AJ12: =COUNTIF(C12:AI12,"P") -> 0 | AK12: =COUNTIF(D12:AI12,"A") -> 0 | AL12: =COUNTIF(D12:AI12,"H") -> 0 | AM12: =COUNTIF(D12:AI12,"TR") -> 0 | AN12: =COUNTIF(D12:AI12,"CL") -> 0 | AO12: =COUNTIF(D12:AI12,"SL") -> 0 | AP12: =COUNTIF(D12:AI12,"AL") -> 0 | AQ12: =COUNTIF(D12:AI12,"ML") -> 0 | AR12: =COUNTIF(D12:AI12,"PL") -> 0 | AS12: =COUNTIF(D12:AI12,"WFH") -> 0 | AT12: =COUNTIF(D12:AI12,"NH") -> 0 | AU12: =SUM(AJ12:AT12) -> 0 | AW12: 22
B13: Solomon Kiwunda | C13: VUEMP018 | AJ13: =COUNTIF(C13:AI13,"P") -> 0 | AK13: =COUNTIF(D13:AI13,"A") -> 0 | AL13: =COUNTIF(D13:AI13,"H") -> 0 | AM13: =COUNTIF(D13:AI13,"TR") -> 0 | AN13: =COUNTIF(D13:AI13,"CL") -> 0 | AO13: =COUNTIF(D13:AI13,"SL") -> 0 | AP13: =COUNTIF(D13:AI13,"AL") -> 0 | AQ13: =COUNTIF(D13:AI13,"ML") -> 0 | AR13: =COUNTIF(D13:AI13,"PL") -> 0 | AS13: =COUNTIF(D13:AI13,"WFH") -> 0 | AT13: =COUNTIF(D13:AI13,"NH") -> 0 | AU13: =SUM(AJ13:AT13) -> 0 | AW13: 21

Sheet UG September 2026
B2: Month | C2: 46266 | D2: 45901 | E2: 45902 | F2: 45903 | G2: 45904 | H2: 45905 | I2: 45906 | J2: 45907 | K2: 45908 | L2: 45909 | M2: 45910 | N2: 45911 | O2: 45912 | P2: 45913 | Q2: 45914 | R2: 45915 | S2: 45916 | T2: 45917 | U2: 45918 | V2: 45919 | W2: 45920 | X2: 45921 | Y2: 45922 | Z2: 45923 | AA2: 45924 | AB2: 45925 | AC2: 45926 | AD2: 45927 | AE2: 45928 | AF2: 45929 | AG2: 45930 | AJ2: Present | AK2: Absent | AL2: Half day | AM2: Training | AN2: Casual Leave | AO2: Sick Leave | AP2: Annual Leave | AQ2: Maternity Leave | AR2: Paternity Leave | AS2: Work Feom Home | AT2: National Holiday | AU2: Total
B3: Employee Name | C3: ID | D3: Tue | E3: Wed | F3: Thu | G3: Fri | H3: Sat | I3: Sun | J3: Mon | K3: Tue | L3: Wed | M3: Thu | N3: Fri | O3: Sat | P3: Sun | Q3: Mon | R3: Tue | S3: Wed | T3: Thu | U3: Fri | V3: Sat | W3: Sun | X3: Mon | Y3: Tue | Z3: Wed | AA3: Thu | AB3: Fri | AC3: Sat | AD3: Sun | AE3: Mon | AF3: Tue | AG3: Wed | AJ3: P | AK3: AB | AL3: HD | AM3: TR | AN3: CL | AO3: SL | AP3: AL | AQ3: ML | AR3: PL | AS3: WH | AT3: NH
B4: Nyinimuntu Angela | C4: VUEMP001 | AJ4: =COUNTIF(C4:AI4,"P") -> 0 | AK4: =COUNTIF(D4:AI4,"A") -> 0 | AL4: =COUNTIF(D4:AI4,"H") -> 0 | AM4: =COUNTIF(D4:AI4,"TR") -> 0 | AN4: =COUNTIF(D4:AI4,"CL") -> 0 | AO4: =COUNTIF(D4:AI4,"SL") -> 0 | AP4: =COUNTIF(D4:AI4,"AL") -> 0 | AQ4: =COUNTIF(D4:AI4,"ML") -> 0 | AR4: =COUNTIF(D4:AI4,"PL") -> 0 | AS4: =COUNTIF(D4:AI4,"WFH") -> 0 | AT4: =COUNTIF(D4:AI4,"NH") -> 0 | AU4: =SUM(AJ4:AT4) -> 0
B5: Joseph Opolot | C5: VUEMP002 | AJ5: =COUNTIF(C5:AI5,"P") -> 0 | AK5: =COUNTIF(D5:AI5,"A") -> 0 | AL5: =COUNTIF(D5:AI5,"H") -> 0 | AM5: =COUNTIF(D5:AI5,"TR") -> 0 | AN5: =COUNTIF(D5:AI5,"CL") -> 0 | AO5: =COUNTIF(D5:AI5,"SL") -> 0 | AP5: =COUNTIF(D5:AI5,"AL") -> 0 | AQ5: =COUNTIF(D5:AI5,"ML") -> 0 | AR5: =COUNTIF(D5:AI5,"PL") -> 0 | AS5: =COUNTIF(D5:AI5,"WFH") -> 0 | AT5: =COUNTIF(D5:AI5,"NH") -> 0 | AU5: =SUM(AJ5:AT5) -> 0
B6: Moses Ikwara | C6: VUEMP004 | AJ6: =COUNTIF(C6:AI6,"P") -> 0 | AK6: =COUNTIF(D6:AI6,"A") -> 0 | AL6: =COUNTIF(D6:AI6,"H") -> 0 | AM6: =COUNTIF(D6:AI6,"TR") -> 0 | AN6: =COUNTIF(D6:AI6,"CL") -> 0 | AO6: =COUNTIF(D6:AI6,"SL") -> 0 | AP6: =COUNTIF(D6:AI6,"AL") -> 0 | AQ6: =COUNTIF(D6:AI6,"ML") -> 0 | AR6: =COUNTIF(D6:AI6,"PL") -> 0 | AS6: =COUNTIF(D6:AI6,"WFH") -> 0 | AT6: =COUNTIF(D6:AI6,"NH") -> 0 | AU6: =SUM(AJ6:AT6) -> 0
B7: Hawa Sirikye | C7: VUEMP005 | AJ7: =COUNTIF(C7:AI7,"P") -> 0 | AK7: =COUNTIF(D7:AI7,"A") -> 0 | AL7: =COUNTIF(D7:AI7,"H") -> 0 | AM7: =COUNTIF(D7:AI7,"TR") -> 0 | AN7: =COUNTIF(D7:AI7,"CL") -> 0 | AO7: =COUNTIF(D7:AI7,"SL") -> 0 | AP7: =COUNTIF(D7:AI7,"AL") -> 0 | AQ7: =COUNTIF(D7:AI7,"ML") -> 0 | AR7: =COUNTIF(D7:AI7,"PL") -> 0 | AS7: =COUNTIF(D7:AI7,"WFH") -> 0 | AT7: =COUNTIF(D7:AI7,"NH") -> 0 | AU7: =SUM(AJ7:AT7) -> 0
B8: Aneesh Mathew | C8: VUEMP008 | AJ8: =COUNTIF(C8:AI8,"P") -> 0 | AK8: =COUNTIF(D8:AI8,"A") -> 0 | AL8: =COUNTIF(D8:AI8,"H") -> 0 | AM8: =COUNTIF(D8:AI8,"TR") -> 0 | AN8: =COUNTIF(D8:AI8,"CL") -> 0 | AO8: =COUNTIF(D8:AI8,"SL") -> 0 | AP8: =COUNTIF(D8:AI8,"AL") -> 0 | AQ8: =COUNTIF(D8:AI8,"ML") -> 0 | AR8: =COUNTIF(D8:AI8,"PL") -> 0 | AS8: =COUNTIF(D8:AI8,"WFH") -> 0 | AT8: =COUNTIF(D8:AI8,"NH") -> 0 | AU8: =SUM(AJ8:AT8) -> 0
B9: Atim Bernadatte | C9: VUEMP009 | AJ9: =COUNTIF(C9:AI9,"P") -> 0 | AK9: =COUNTIF(D9:AI9,"A") -> 0 | AL9: =COUNTIF(D9:AI9,"H") -> 0 | AM9: =COUNTIF(D9:AI9,"TR") -> 0 | AN9: =COUNTIF(D9:AI9,"CL") -> 0 | AO9: =COUNTIF(D9:AI9,"SL") -> 0 | AP9: =COUNTIF(D9:AI9,"AL") -> 0 | AQ9: =COUNTIF(D9:AI9,"ML") -> 0 | AR9: =COUNTIF(D9:AI9,"PL") -> 0 | AS9: =COUNTIF(D9:AI9,"WFH") -> 0 | AT9: =COUNTIF(D9:AI9,"NH") -> 0 | AU9: =SUM(AJ9:AT9) -> 0
B10: Kawunde Paul | C10: VUEMP011 | AJ10: =COUNTIF(C10:AI10,"P") -> 0 | AK10: =COUNTIF(D10:AI10,"A") -> 0 | AL10: =COUNTIF(D10:AI10,"H") -> 0 | AM10: =COUNTIF(D10:AI10,"TR") -> 0 | AN10: =COUNTIF(D10:AI10,"CL") -> 0 | AO10: =COUNTIF(D10:AI10,"SL") -> 0 | AP10: =COUNTIF(D10:AI10,"AL") -> 0 | AQ10: =COUNTIF(D10:AI10,"ML") -> 0 | AR10: =COUNTIF(D10:AI10,"PL") -> 0 | AS10: =COUNTIF(D10:AI10,"WFH") -> 0 | AT10: =COUNTIF(D10:AI10,"NH") -> 0 | AU10: =SUM(AJ10:AT10) -> 0
B11: Lubega Joel Brian | C11: VUEMP015 | AJ11: =COUNTIF(C11:AI11,"P") -> 0 | AK11: =COUNTIF(D11:AI11,"A") -> 0 | AL11: =COUNTIF(D11:AI11,"H") -> 0 | AM11: =COUNTIF(D11:AI11,"TR") -> 0 | AN11: =COUNTIF(D11:AI11,"CL") -> 0 | AO11: =COUNTIF(D11:AI11,"SL") -> 0 | AP11: =COUNTIF(D11:AI11,"AL") -> 0 | AQ11: =COUNTIF(D11:AI11,"ML") -> 0 | AR11: =COUNTIF(D11:AI11,"PL") -> 0 | AS11: =COUNTIF(D11:AI11,"WFH") -> 0 | AT11: =COUNTIF(D11:AI11,"NH") -> 0 | AU11: =SUM(AJ11:AT11) -> 0
B12: Joseph Wetaka Wandega | C12: VUEMP017 | AJ12: =COUNTIF(C12:AI12,"P") -> 0 | AK12: =COUNTIF(D12:AI12,"A") -> 0 | AL12: =COUNTIF(D12:AI12,"H") -> 0 | AM12: =COUNTIF(D12:AI12,"TR") -> 0 | AN12: =COUNTIF(D12:AI12,"CL") -> 0 | AO12: =COUNTIF(D12:AI12,"SL") -> 0 | AP12: =COUNTIF(D12:AI12,"AL") -> 0 | AQ12: =COUNTIF(D12:AI12,"ML") -> 0 | AR12: =COUNTIF(D12:AI12,"PL") -> 0 | AS12: =COUNTIF(D12:AI12,"WFH") -> 0 | AT12: =COUNTIF(D12:AI12,"NH") -> 0 | AU12: =SUM(AJ12:AT12) -> 0
B13: Solomon Kiwunda | C13: VUEMP018 | AJ13: =COUNTIF(C13:AI13,"P") -> 0 | AK13: =COUNTIF(D13:AI13,"A") -> 0 | AL13: =COUNTIF(D13:AI13,"H") -> 0 | AM13: =COUNTIF(D13:AI13,"TR") -> 0 | AN13: =COUNTIF(D13:AI13,"CL") -> 0 | AO13: =COUNTIF(D13:AI13,"SL") -> 0 | AP13: =COUNTIF(D13:AI13,"AL") -> 0 | AQ13: =COUNTIF(D13:AI13,"ML") -> 0 | AR13: =COUNTIF(D13:AI13,"PL") -> 0 | AS13: =COUNTIF(D13:AI13,"WFH") -> 0 | AT13: =COUNTIF(D13:AI13,"NH") -> 0 | AU13: =SUM(AJ13:AT13) -> 0

Sheet UG August 2026
B2: Month | C2: 46235 | D2: 45870 | E2: 45871 | F2: 45872 | G2: 45873 | H2: 45874 | I2: 45875 | J2: 45876 | K2: 45877 | L2: 45878 | M2: 45879 | N2: 45880 | O2: 45881 | P2: 45882 | Q2: 45883 | R2: 45884 | S2: 45885 | T2: 45886 | U2: 45887 | V2: 45888 | W2: 45889 | X2: 45890 | Y2: 45891 | Z2: 45892 | AA2: 45893 | AB2: 45894 | AC2: 45895 | AD2: 45896 | AE2: 45897 | AF2: 45898 | AG2: 45899 | AH2: 45900 | AJ2: Present | AK2: Absent | AL2: Half day | AM2: Training | AN2: Casual Leave | AO2: Sick Leave | AP2: Annual Leave | AQ2: Maternity Leave | AR2: Paternity Leave | AS2: Work Feom Home | AT2: National Holiday | AU2: Total
B3: Employee Name | C3: ID | D3: Sat | E3: Sun | F3: Mon | G3: Tue | H3: Wed | I3: Thu | J3: Fri | K3: Sat | L3: Sun | M3: Mon | N3: Tue | O3: Wed | P3: Thu | Q3: Fri | R3: Sat | S3: Sun | T3: Mon | U3: Tue | V3: Wed | W3: Thu | X3: Fri | Y3: Sat | Z3: Sun | AA3: Mon | AB3: Tue | AC3: Wed | AD3: Thu | AE3: Fri | AF3: Sat | AG3: Sun | AH3: Mon | AJ3: P | AK3: AB | AL3: HD | AM3: TR | AN3: CL | AO3: SL | AP3: AL | AQ3: ML | AR3: PL | AS3: WH | AT3: NH
B4: Nyinimuntu Angela | C4: VUEMP001 | AJ4: =COUNTIF(C4:AI4,"P") -> 0 | AK4: =COUNTIF(D4:AI4,"A") -> 0 | AL4: =COUNTIF(D4:AI4,"H") -> 0 | AM4: =COUNTIF(D4:AI4,"TR") -> 0 | AN4: =COUNTIF(D4:AI4,"CL") -> 0 | AO4: =COUNTIF(D4:AI4,"SL") -> 0 | AP4: =COUNTIF(D4:AI4,"AL") -> 0 | AQ4: =COUNTIF(D4:AI4,"ML") -> 0 | AR4: =COUNTIF(D4:AI4,"PL") -> 0 | AS4: =COUNTIF(D4:AI4,"WFH") -> 0 | AT4: =COUNTIF(D4:AI4,"NH") -> 0 | AU4: =SUM(AJ4:AT4) -> 0
B5: Joseph Opolot | C5: VUEMP002 | AJ5: =COUNTIF(C5:AI5,"P") -> 0 | AK5: =COUNTIF(D5:AI5,"A") -> 0 | AL5: =COUNTIF(D5:AI5,"H") -> 0 | AM5: =COUNTIF(D5:AI5,"TR") -> 0 | AN5: =COUNTIF(D5:AI5,"CL") -> 0 | AO5: =COUNTIF(D5:AI5,"SL") -> 0 | AP5: =COUNTIF(D5:AI5,"AL") -> 0 | AQ5: =COUNTIF(D5:AI5,"ML") -> 0 | AR5: =COUNTIF(D5:AI5,"PL") -> 0 | AS5: =COUNTIF(D5:AI5,"WFH") -> 0 | AT5: =COUNTIF(D5:AI5,"NH") -> 0 | AU5: =SUM(AJ5:AT5) -> 0
B6: Moses Ikwara | C6: VUEMP004 | AJ6: =COUNTIF(C6:AI6,"P") -> 0 | AK6: =COUNTIF(D6:AI6,"A") -> 0 | AL6: =COUNTIF(D6:AI6,"H") -> 0 | AM6: =COUNTIF(D6:AI6,"TR") -> 0 | AN6: =COUNTIF(D6:AI6,"CL") -> 0 | AO6: =COUNTIF(D6:AI6,"SL") -> 0 | AP6: =COUNTIF(D6:AI6,"AL") -> 0 | AQ6: =COUNTIF(D6:AI6,"ML") -> 0 | AR6: =COUNTIF(D6:AI6,"PL") -> 0 | AS6: =COUNTIF(D6:AI6,"WFH") -> 0 | AT6: =COUNTIF(D6:AI6,"NH") -> 0 | AU6: =SUM(AJ6:AT6) -> 0
B7: Hawa Sirikye | C7: VUEMP005 | AJ7: =COUNTIF(C7:AI7,"P") -> 0 | AK7: =COUNTIF(D7:AI7,"A") -> 0 | AL7: =COUNTIF(D7:AI7,"H") -> 0 | AM7: =COUNTIF(D7:AI7,"TR") -> 0 | AN7: =COUNTIF(D7:AI7,"CL") -> 0 | AO7: =COUNTIF(D7:AI7,"SL") -> 0 | AP7: =COUNTIF(D7:AI7,"AL") -> 0 | AQ7: =COUNTIF(D7:AI7,"ML") -> 0 | AR7: =COUNTIF(D7:AI7,"PL") -> 0 | AS7: =COUNTIF(D7:AI7,"WFH") -> 0 | AT7: =COUNTIF(D7:AI7,"NH") -> 0 | AU7: =SUM(AJ7:AT7) -> 0
B8: Aneesh Mathew | C8: VUEMP008 | AJ8: =COUNTIF(C8:AI8,"P") -> 0 | AK8: =COUNTIF(D8:AI8,"A") -> 0 | AL8: =COUNTIF(D8:AI8,"H") -> 0 | AM8: =COUNTIF(D8:AI8,"TR") -> 0 | AN8: =COUNTIF(D8:AI8,"CL") -> 0 | AO8: =COUNTIF(D8:AI8,"SL") -> 0 | AP8: =COUNTIF(D8:AI8,"AL") -> 0 | AQ8: =COUNTIF(D8:AI8,"ML") -> 0 | AR8: =COUNTIF(D8:AI8,"PL") -> 0 | AS8: =COUNTIF(D8:AI8,"WFH") -> 0 | AT8: =COUNTIF(D8:AI8,"NH") -> 0 | AU8: =SUM(AJ8:AT8) -> 0
B9: Atim Bernadatte | C9: VUEMP009 | AJ9: =COUNTIF(C9:AI9,"P") -> 0 | AK9: =COUNTIF(D9:AI9,"A") -> 0 | AL9: =COUNTIF(D9:AI9,"H") -> 0 | AM9: =COUNTIF(D9:AI9,"TR") -> 0 | AN9: =COUNTIF(D9:AI9,"CL") -> 0 | AO9: =COUNTIF(D9:AI9,"SL") -> 0 | AP9: =COUNTIF(D9:AI9,"AL") -> 0 | AQ9: =COUNTIF(D9:AI9,"ML") -> 0 | AR9: =COUNTIF(D9:AI9,"PL") -> 0 | AS9: =COUNTIF(D9:AI9,"WFH") -> 0 | AT9: =COUNTIF(D9:AI9,"NH") -> 0 | AU9: =SUM(AJ9:AT9) -> 0
B10: Kawunde Paul | C10: VUEMP011 | AJ10: =COUNTIF(C10:AI10,"P") -> 0 | AK10: =COUNTIF(D10:AI10,"A") -> 0 | AL10: =COUNTIF(D10:AI10,"H") -> 0 | AM10: =COUNTIF(D10:AI10,"TR") -> 0 | AN10: =COUNTIF(D10:AI10,"CL") -> 0 | AO10: =COUNTIF(D10:AI10,"SL") -> 0 | AP10: =COUNTIF(D10:AI10,"AL") -> 0 | AQ10: =COUNTIF(D10:AI10,"ML") -> 0 | AR10: =COUNTIF(D10:AI10,"PL") -> 0 | AS10: =COUNTIF(D10:AI10,"WFH") -> 0 | AT10: =COUNTIF(D10:AI10,"NH") -> 0 | AU10: =SUM(AJ10:AT10) -> 0
B11: Lubega Joel Brian | C11: VUEMP015 | AJ11: =COUNTIF(C11:AI11,"P") -> 0 | AK11: =COUNTIF(D11:AI11,"A") -> 0 | AL11: =COUNTIF(D11:AI11,"H") -> 0 | AM11: =COUNTIF(D11:AI11,"TR") -> 0 | AN11: =COUNTIF(D11:AI11,"CL") -> 0 | AO11: =COUNTIF(D11:AI11,"SL") -> 0 | AP11: =COUNTIF(D11:AI11,"AL") -> 0 | AQ11: =COUNTIF(D11:AI11,"ML") -> 0 | AR11: =COUNTIF(D11:AI11,"PL") -> 0 | AS11: =COUNTIF(D11:AI11,"WFH") -> 0 | AT11: =COUNTIF(D11:AI11,"NH") -> 0 | AU11: =SUM(AJ11:AT11) -> 0
B12: Joseph Wetaka Wandega | C12: VUEMP017 | AJ12: =COUNTIF(C12:AI12,"P") -> 0 | AK12: =COUNTIF(D12:AI12,"A") -> 0 | AL12: =COUNTIF(D12:AI12,"H") -> 0 | AM12: =COUNTIF(D12:AI12,"TR") -> 0 | AN12: =COUNTIF(D12:AI12,"CL") -> 0 | AO12: =COUNTIF(D12:AI12,"SL") -> 0 | AP12: =COUNTIF(D12:AI12,"AL") -> 0 | AQ12: =COUNTIF(D12:AI12,"ML") -> 0 | AR12: =COUNTIF(D12:AI12,"PL") -> 0 | AS12: =COUNTIF(D12:AI12,"WFH") -> 0 | AT12: =COUNTIF(D12:AI12,"NH") -> 0 | AU12: =SUM(AJ12:AT12) -> 0
B13: Solomon Kiwunda | C13: VUEMP018 | AJ13: =COUNTIF(C13:AI13,"P") -> 0 | AK13: =COUNTIF(D13:AI13,"A") -> 0 | AL13: =COUNTIF(D13:AI13,"H") -> 0 | AM13: =COUNTIF(D13:AI13,"TR") -> 0 | AN13: =COUNTIF(D13:AI13,"CL") -> 0 | AO13: =COUNTIF(D13:AI13,"SL") -> 0 | AP13: =COUNTIF(D13:AI13,"AL") -> 0 | AQ13: =COUNTIF(D13:AI13,"ML") -> 0 | AR13: =COUNTIF(D13:AI13,"PL") -> 0 | AS13: =COUNTIF(D13:AI13,"WFH") -> 0 | AT13: =COUNTIF(D13:AI13,"NH") -> 0 | AU13: =SUM(AJ13:AT13) -> 0

Sheet UG July 2026
B2: Month | C2: 46204 | D2: 45839 | E2: 45840 | F2: 45841 | G2: 45842 | H2: 45843 | I2: 45844 | J2: 45845 | K2: 45846 | L2: 45847 | M2: 45848 | N2: 45849 | O2: 45850 | P2: 45851 | Q2: 45852 | R2: 45853 | S2: 45854 | T2: 45855 | U2: 45856 | V2: 45857 | W2: 45858 | X2: 45859 | Y2: 45860 | Z2: 45861 | AA2: 45862 | AB2: 45863 | AC2: 45864 | AD2: 45865 | AE2: 45866 | AF2: 45867 | AG2: 45868 | AH2: 45869 | AJ2: Present | AK2: Absent | AL2: Half day | AM2: Training | AN2: Casual Leave | AO2: Sick Leave | AP2: Annual Leave | AQ2: Maternity Leave | AR2: Paternity Leave | AS2: Work Feom Home | AT2: National Holiday | AU2: Total
B3: Employee Name | C3: ID | D3: Wed | E3: Thu | F3: Fri | G3: Sat | H3: Sun | I3: Mon | J3: Tue | K3: Wed | L3: Thu | M3: Fri | N3: Sat | O3: Sun | P3: Mon | Q3: Tue | R3: Wed | S3: Thu | T3: Fri | U3: Sat | V3: Sun | W3: Mon | X3: Tue | Y3: Wed | Z3: Thu | AA3: Fri | AB3: Sat | AC3: Sun | AD3: Mon | AE3: Tue | AF3: Wed | AG3: Thu | AH3: Fri | AJ3: P | AK3: AB | AL3: HD | AM3: TR | AN3: CL | AO3: SL | AP3: AL | AQ3: ML | AR3: PL | AS3: WH | AT3: NH
B4: Nyinimuntu Angela | C4: VUEMP001 | AJ4: =COUNTIF(C4:AH4,"P") -> 0 | AK4: =COUNTIF(D4:AH4,"A") -> 0 | AL4: =COUNTIF(D4:AH4,"H") -> 0 | AM4: =COUNTIF(D4:AH4,"TR") -> 0 | AN4: =COUNTIF(D4:AH4,"CL") -> 0 | AO4: =COUNTIF(D4:AH4,"SL") -> 0 | AP4: =COUNTIF(D4:AH4,"AL") -> 0 | AQ4: =COUNTIF(D4:AH4,"ML") -> 0 | AR4: =COUNTIF(D4:AH4,"PL") -> 0 | AS4: =COUNTIF(D4:AH4,"WFH") -> 0 | AT4: =COUNTIF(D4:AH4,"NH") -> 0 | AU4: =SUM(AJ4:AT4) -> 0
B5: Joseph Opolot | C5: VUEMP002 | AJ5: =COUNTIF(C5:AH5,"P") -> 0 | AK5: =COUNTIF(D5:AH5,"A") -> 0 | AL5: =COUNTIF(D5:AH5,"H") -> 0 | AM5: =COUNTIF(D5:AH5,"TR") -> 0 | AN5: =COUNTIF(D5:AH5,"CL") -> 0 | AO5: =COUNTIF(D5:AH5,"SL") -> 0 | AP5: =COUNTIF(D5:AH5,"AL") -> 0 | AQ5: =COUNTIF(D5:AH5,"ML") -> 0 | AR5: =COUNTIF(D5:AH5,"PL") -> 0 | AS5: =COUNTIF(D5:AH5,"WFH") -> 0 | AT5: =COUNTIF(D5:AH5,"NH") -> 0 | AU5: =SUM(AJ5:AT5) -> 0
B6: Moses Ikwara | C6: VUEMP004 | AJ6: =COUNTIF(C6:AH6,"P") -> 0 | AK6: =COUNTIF(D6:AH6,"A") -> 0 | AL6: =COUNTIF(D6:AH6,"H") -> 0 | AM6: =COUNTIF(D6:AH6,"TR") -> 0 | AN6: =COUNTIF(D6:AH6,"CL") -> 0 | AO6: =COUNTIF(D6:AH6,"SL") -> 0 | AP6: =COUNTIF(D6:AH6,"AL") -> 0 | AQ6: =COUNTIF(D6:AH6,"ML") -> 0 | AR6: =COUNTIF(D6:AH6,"PL") -> 0 | AS6: =COUNTIF(D6:AH6,"WFH") -> 0 | AT6: =COUNTIF(D6:AH6,"NH") -> 0 | AU6: =SUM(AJ6:AT6) -> 0
B7: Hawa Sirikye | C7: VUEMP005 | AJ7: =COUNTIF(C7:AH7,"P") -> 0 | AK7: =COUNTIF(D7:AH7,"A") -> 0 | AL7: =COUNTIF(D7:AH7,"H") -> 0 | AM7: =COUNTIF(D7:AH7,"TR") -> 0 | AN7: =COUNTIF(D7:AH7,"CL") -> 0 | AO7: =COUNTIF(D7:AH7,"SL") -> 0 | AP7: =COUNTIF(D7:AH7,"AL") -> 0 | AQ7: =COUNTIF(D7:AH7,"ML") -> 0 | AR7: =COUNTIF(D7:AH7,"PL") -> 0 | AS7: =COUNTIF(D7:AH7,"WFH") -> 0 | AT7: =COUNTIF(D7:AH7,"NH") -> 0 | AU7: =SUM(AJ7:AT7) -> 0
B8: Aneesh Mathew | C8: VUEMP008 | AJ8: =COUNTIF(C8:AH8,"P") -> 0 | AK8: =COUNTIF(D8:AH8,"A") -> 0 | AL8: =COUNTIF(D8:AH8,"H") -> 0 | AM8: =COUNTIF(D8:AH8,"TR") -> 0 | AN8: =COUNTIF(D8:AH8,"CL") -> 0 | AO8: =COUNTIF(D8:AH8,"SL") -> 0 | AP8: =COUNTIF(D8:AH8,"AL") -> 0 | AQ8: =COUNTIF(D8:AH8,"ML") -> 0 | AR8: =COUNTIF(D8:AH8,"PL") -> 0 | AS8: =COUNTIF(D8:AH8,"WFH") -> 0 | AT8: =COUNTIF(D8:AH8,"NH") -> 0 | AU8: =SUM(AJ8:AT8) -> 0
B9: Atim Bernadatte | C9: VUEMP009 | AJ9: =COUNTIF(C9:AH9,"P") -> 0 | AK9: =COUNTIF(D9:AH9,"A") -> 0 | AL9: =COUNTIF(D9:AH9,"H") -> 0 | AM9: =COUNTIF(D9:AH9,"TR") -> 0 | AN9: =COUNTIF(D9:AH9,"CL") -> 0 | AO9: =COUNTIF(D9:AH9,"SL") -> 0 | AP9: =COUNTIF(D9:AH9,"AL") -> 0 | AQ9: =COUNTIF(D9:AH9,"ML") -> 0 | AR9: =COUNTIF(D9:AH9,"PL") -> 0 | AS9: =COUNTIF(D9:AH9,"WFH") -> 0 | AT9: =COUNTIF(D9:AH9,"NH") -> 0 | AU9: =SUM(AJ9:AT9) -> 0
B10: Kawunde Paul | C10: VUEMP011 | AJ10: =COUNTIF(C10:AH10,"P") -> 0 | AK10: =COUNTIF(D10:AH10,"A") -> 0 | AL10: =COUNTIF(D10:AH10,"H") -> 0 | AM10: =COUNTIF(D10:AH10,"TR") -> 0 | AN10: =COUNTIF(D10:AH10,"CL") -> 0 | AO10: =COUNTIF(D10:AH10,"SL") -> 0 | AP10: =COUNTIF(D10:AH10,"AL") -> 0 | AQ10: =COUNTIF(D10:AH10,"ML") -> 0 | AR10: =COUNTIF(D10:AH10,"PL") -> 0 | AS10: =COUNTIF(D10:AH10,"WFH") -> 0 | AT10: =COUNTIF(D10:AH10,"NH") -> 0 | AU10: =SUM(AJ10:AT10) -> 0
B11: Lubega Joel Brian | C11: VUEMP015 | AJ11: =COUNTIF(C11:AH11,"P") -> 0 | AK11: =COUNTIF(D11:AH11,"A") -> 0 | AL11: =COUNTIF(D11:AH11,"H") -> 0 | AM11: =COUNTIF(D11:AH11,"TR") -> 0 | AN11: =COUNTIF(D11:AH11,"CL") -> 0 | AO11: =COUNTIF(D11:AH11,"SL") -> 0 | AP11: =COUNTIF(D11:AH11,"AL") -> 0 | AQ11: =COUNTIF(D11:AH11,"ML") -> 0 | AR11: =COUNTIF(D11:AH11,"PL") -> 0 | AS11: =COUNTIF(D11:AH11,"WFH") -> 0 | AT11: =COUNTIF(D11:AH11,"NH") -> 0 | AU11: =SUM(AJ11:AT11) -> 0
B12: Joseph Wetaka Wandega | C12: VUEMP017 | AJ12: =COUNTIF(C12:AH12,"P") -> 0 | AK12: =COUNTIF(D12:AH12,"A") -> 0 | AL12: =COUNTIF(D12:AH12,"H") -> 0 | AM12: =COUNTIF(D12:AH12,"TR") -> 0 | AN12: =COUNTIF(D12:AH12,"CL") -> 0 | AO12: =COUNTIF(D12:AH12,"SL") -> 0 | AP12: =COUNTIF(D12:AH12,"AL") -> 0 | AQ12: =COUNTIF(D12:AH12,"ML") -> 0 | AR12: =COUNTIF(D12:AH12,"PL") -> 0 | AS12: =COUNTIF(D12:AH12,"WFH") -> 0 | AT12: =COUNTIF(D12:AH12,"NH") -> 0 | AU12: =SUM(AJ12:AT12) -> 0
B13: Solomon Kiwunda | C13: VUEMP018 | AJ13: =COUNTIF(C13:AH13,"P") -> 0 | AK13: =COUNTIF(D13:AH13,"A") -> 0 | AL13: =COUNTIF(D13:AH13,"H") -> 0 | AM13: =COUNTIF(D13:AH13,"TR") -> 0 | AN13: =COUNTIF(D13:AH13,"CL") -> 0 | AO13: =COUNTIF(D13:AH13,"SL") -> 0 | AP13: =COUNTIF(D13:AH13,"AL") -> 0 | AQ13: =COUNTIF(D13:AH13,"ML") -> 0 | AR13: =COUNTIF(D13:AH13,"PL") -> 0 | AS13: =COUNTIF(D13:AH13,"WFH") -> 0 | AT13: =COUNTIF(D13:AH13,"NH") -> 0 | AU13: =SUM(AJ13:AT13) -> 0

Sheet UG June 2026
B2: Month | C2: 45809 | D2: 45809 | E2: 45810 | F2: 45811 | G2: 45812 | H2: 45813 | I2: 45814 | J2: 45815 | K2: 45816 | L2: 45817 | M2: 45818 | N2: 45819 | O2: 45820 | P2: 45821 | Q2: 45822 | R2: 45823 | S2: 45824 | T2: 45825 | U2: 45826 | V2: 45827 | W2: 45828 | X2: 45829 | Y2: 45830 | Z2: 45831 | AA2: 45832 | AB2: 45833 | AC2: 45834 | AD2: 45835 | AE2: 45836 | AF2: 45837 | AG2: 45838 | AJ2: Present | AK2: Absent | AL2: Half day | AM2: Training | AN2: Casual Leave | AO2: Sick Leave | AP2: Annual Leave | AQ2: Maternity Leave | AR2: Paternity Leave | AS2: Work Feom Home | AT2: National Holiday | AU2: Total
B3: Employee Name | C3: ID | D3: Mon | E3: Tue | F3: Wed | G3: Thu | H3: Fri | I3: Sat | J3: Sun | K3: Mon | L3: Tue | M3: Wed | N3: Thu | O3: Fri | P3: Sat | Q3: Sun | R3: Mon | S3: Tue | T3: Wed | U3: Thu | V3: Fri | W3: Sat | X3: Sun | Y3: Mon | Z3: Tue | AA3: Wed | AB3: Thu | AC3: Fri | AD3: Sat | AE3: Sun | AF3: Mon | AG3: Tue | AJ3: P | AK3: AB | AL3: HD | AM3: TR | AN3: CL | AO3: SL | AP3: AL | AQ3: ML | AR3: PL | AS3: WH | AT3: NH
B4: Nyinimuntu Angela | C4: VUEMP001 | AJ4: =COUNTIF(C4:AI4,"P") -> 0 | AK4: =COUNTIF(D4:AI4,"A") -> 0 | AL4: =COUNTIF(D4:AI4,"H") -> 0 | AM4: =COUNTIF(D4:AI4,"TR") -> 0 | AN4: =COUNTIF(D4:AI4,"CL") -> 0 | AO4: =COUNTIF(D4:AI4,"SL") -> 0 | AP4: =COUNTIF(D4:AI4,"AL") -> 0 | AQ4: =COUNTIF(D4:AI4,"ML") -> 0 | AR4: =COUNTIF(D4:AI4,"PL") -> 0 | AS4: =COUNTIF(D4:AI4,"WFH") -> 0 | AT4: =COUNTIF(D4:AI4,"NH") -> 0 | AU4: =SUM(AJ4:AT4) -> 0
B5: Joseph Opolot | C5: VUEMP002 | AJ5: =COUNTIF(C5:AI5,"P") -> 0 | AK5: =COUNTIF(D5:AI5,"A") -> 0 | AL5: =COUNTIF(D5:AI5,"H") -> 0 | AM5: =COUNTIF(D5:AI5,"TR") -> 0 | AN5: =COUNTIF(D5:AI5,"CL") -> 0 | AO5: =COUNTIF(D5:AI5,"SL") -> 0 | AP5: =COUNTIF(D5:AI5,"AL") -> 0 | AQ5: =COUNTIF(D5:AI5,"ML") -> 0 | AR5: =COUNTIF(D5:AI5,"PL") -> 0 | AS5: =COUNTIF(D5:AI5,"WFH") -> 0 | AT5: =COUNTIF(D5:AI5,"NH") -> 0 | AU5: =SUM(AJ5:AT5) -> 0
B6: Moses Ikwara | C6: VUEMP004 | AJ6: =COUNTIF(C6:AI6,"P") -> 0 | AK6: =COUNTIF(D6:AI6,"A") -> 0 | AL6: =COUNTIF(D6:AI6,"H") -> 0 | AM6: =COUNTIF(D6:AI6,"TR") -> 0 | AN6: =COUNTIF(D6:AI6,"CL") -> 0 | AO6: =COUNTIF(D6:AI6,"SL") -> 0 | AP6: =COUNTIF(D6:AI6,"AL") -> 0 | AQ6: =COUNTIF(D6:AI6,"ML") -> 0 | AR6: =COUNTIF(D6:AI6,"PL") -> 0 | AS6: =COUNTIF(D6:AI6,"WFH") -> 0 | AT6: =COUNTIF(D6:AI6,"NH") -> 0 | AU6: =SUM(AJ6:AT6) -> 0
B7: Hawa Sirikye | C7: VUEMP005 | AJ7: =COUNTIF(C7:AI7,"P") -> 0 | AK7: =COUNTIF(D7:AI7,"A") -> 0 | AL7: =COUNTIF(D7:AI7,"H") -> 0 | AM7: =COUNTIF(D7:AI7,"TR") -> 0 | AN7: =COUNTIF(D7:AI7,"CL") -> 0 | AO7: =COUNTIF(D7:AI7,"SL") -> 0 | AP7: =COUNTIF(D7:AI7,"AL") -> 0 | AQ7: =COUNTIF(D7:AI7,"ML") -> 0 | AR7: =COUNTIF(D7:AI7,"PL") -> 0 | AS7: =COUNTIF(D7:AI7,"WFH") -> 0 | AT7: =COUNTIF(D7:AI7,"NH") -> 0 | AU7: =SUM(AJ7:AT7) -> 0
B8: Aneesh Mathew | C8: VUEMP008 | AJ8: =COUNTIF(C8:AI8,"P") -> 0 | AK8: =COUNTIF(D8:AI8,"A") -> 0 | AL8: =COUNTIF(D8:AI8,"H") -> 0 | AM8: =COUNTIF(D8:AI8,"TR") -> 0 | AN8: =COUNTIF(D8:AI8,"CL") -> 0 | AO8: =COUNTIF(D8:AI8,"SL") -> 0 | AP8: =COUNTIF(D8:AI8,"AL") -> 0 | AQ8: =COUNTIF(D8:AI8,"ML") -> 0 | AR8: =COUNTIF(D8:AI8,"PL") -> 0 | AS8: =COUNTIF(D8:AI8,"WFH") -> 0 | AT8: =COUNTIF(D8:AI8,"NH") -> 0 | AU8: =SUM(AJ8:AT8) -> 0
B9: Atim Bernadatte | C9: VUEMP009 | AJ9: =COUNTIF(C9:AI9,"P") -> 0 | AK9: =COUNTIF(D9:AI9,"A") -> 0 | AL9: =COUNTIF(D9:AI9,"H") -> 0 | AM9: =COUNTIF(D9:AI9,"TR") -> 0 | AN9: =COUNTIF(D9:AI9,"CL") -> 0 | AO9: =COUNTIF(D9:AI9,"SL") -> 0 | AP9: =COUNTIF(D9:AI9,"AL") -> 0 | AQ9: =COUNTIF(D9:AI9,"ML") -> 0 | AR9: =COUNTIF(D9:AI9,"PL") -> 0 | AS9: =COUNTIF(D9:AI9,"WFH") -> 0 | AT9: =COUNTIF(D9:AI9,"NH") -> 0 | AU9: =SUM(AJ9:AT9) -> 0
B10: Kawunde Paul | C10: VUEMP011 | AJ10: =COUNTIF(C10:AI10,"P") -> 0 | AK10: =COUNTIF(D10:AI10,"A") -> 0 | AL10: =COUNTIF(D10:AI10,"H") -> 0 | AM10: =COUNTIF(D10:AI10,"TR") -> 0 | AN10: =COUNTIF(D10:AI10,"CL") -> 0 | AO10: =COUNTIF(D10:AI10,"SL") -> 0 | AP10: =COUNTIF(D10:AI10,"AL") -> 0 | AQ10: =COUNTIF(D10:AI10,"ML") -> 0 | AR10: =COUNTIF(D10:AI10,"PL") -> 0 | AS10: =COUNTIF(D10:AI10,"WFH") -> 0 | AT10: =COUNTIF(D10:AI10,"NH") -> 0 | AU10: =SUM(AJ10:AT10) -> 0
B11: Lubega Joel Brian | C11: VUEMP015 | AJ11: =COUNTIF(C11:AI11,"P") -> 0 | AK11: =COUNTIF(D11:AI11,"A") -> 0 | AL11: =COUNTIF(D11:AI11,"H") -> 0 | AM11: =COUNTIF(D11:AI11,"TR") -> 0 | AN11: =COUNTIF(D11:AI11,"CL") -> 0 | AO11: =COUNTIF(D11:AI11,"SL") -> 0 | AP11: =COUNTIF(D11:AI11,"AL") -> 0 | AQ11: =COUNTIF(D11:AI11,"ML") -> 0 | AR11: =COUNTIF(D11:AI11,"PL") -> 0 | AS11: =COUNTIF(D11:AI11,"WFH") -> 0 | AT11: =COUNTIF(D11:AI11,"NH") -> 0 | AU11: =SUM(AJ11:AT11) -> 0
B12: Joseph Wetaka Wandega | C12: VUEMP017 | AJ12: =COUNTIF(C12:AI12,"P") -> 0 | AK12: =COUNTIF(D12:AI12,"A") -> 0 | AL12: =COUNTIF(D12:AI12,"H") -> 0 | AM12: =COUNTIF(D12:AI12,"TR") -> 0 | AN12: =COUNTIF(D12:AI12,"CL") -> 0 | AO12: =COUNTIF(D12:AI12,"SL") -> 0 | AP12: =COUNTIF(D12:AI12,"AL") -> 0 | AQ12: =COUNTIF(D12:AI12,"ML") -> 0 | AR12: =COUNTIF(D12:AI12,"PL") -> 0 | AS12: =COUNTIF(D12:AI12,"WFH") -> 0 | AT12: =COUNTIF(D12:AI12,"NH") -> 0 | AU12: =SUM(AJ12:AT12) -> 0
B13: Solomon Kiwunda | C13: VUEMP018 | AJ13: =COUNTIF(C13:AI13,"P") -> 0 | AK13: =COUNTIF(D13:AI13,"A") -> 0 | AL13: =COUNTIF(D13:AI13,"H") -> 0 | AM13: =COUNTIF(D13:AI13,"TR") -> 0 | AN13: =COUNTIF(D13:AI13,"CL") -> 0 | AO13: =COUNTIF(D13:AI13,"SL") -> 0 | AP13: =COUNTIF(D13:AI13,"AL") -> 0 | AQ13: =COUNTIF(D13:AI13,"ML") -> 0 | AR13: =COUNTIF(D13:AI13,"PL") -> 0 | AS13: =COUNTIF(D13:AI13,"WFH") -> 0 | AT13: =COUNTIF(D13:AI13,"NH") -> 0 | AU13: =SUM(AJ13:AT13) -> 0

Sheet UG May 2026
B2: Month | C2: 46143 | D2: 45778 | E2: 45779 | F2: 45780 | G2: 45781 | H2: 45782 | I2: 45783 | J2: 45784 | K2: 45785 | L2: 45786 | M2: 45787 | N2: 45788 | O2: 45789 | P2: 45790 | Q2: 45791 | R2: 45792 | S2: 45793 | T2: 45794 | U2: 45795 | V2: 45796 | W2: 45797 | X2: 45798 | Y2: 45799 | Z2: 45800 | AA2: 45801 | AB2: 45802 | AC2: 45803 | AD2: 45804 | AE2: 45805 | AF2: 45806 | AG2: 45807 | AH2: 45808 | AJ2: Present | AK2: Absent | AL2: Half day | AM2: Training | AN2: Casual Leave | AO2: Sick Leave | AP2: Annual Leave | AQ2: Maternity Leave | AR2: Paternity Leave | AS2: Work Feom Home | AT2: National Holiday | AU2: Total
B3: Employee Name | C3: ID | D3: Fri | E3: Sat | F3: Sun | G3: Mon | H3: Tue | I3: Wed | J3: Thu | K3: Fri | L3: Sat | M3: Sun | N3: Mon | O3: Tue | P3: Wed | Q3: Thu | R3: Fri | S3: Sat | T3: Sun | U3: Mon | V3: Tue | W3: Wed | X3: Thu | Y3: Fri | Z3: Sat | AA3: Sun | AB3: Mon | AC3: Tue | AD3: Wed | AE3: Thu | AF3: Fri | AG3: Sat | AH3: Sun | AJ3: P | AK3: AB | AL3: HD | AM3: TR | AN3: CL | AO3: SL | AP3: AL | AQ3: ML | AR3: PL | AS3: WH | AT3: NH
B4: Nyinimuntu Angela | C4: VUEMP001 | AJ4: =COUNTIF(C4:AI4,"P") -> 0 | AK4: =COUNTIF(D4:AI4,"A") -> 0 | AL4: =COUNTIF(D4:AI4,"H") -> 0 | AM4: =COUNTIF(D4:AI4,"TR") -> 0 | AN4: =COUNTIF(D4:AI4,"CL") -> 0 | AO4: =COUNTIF(D4:AI4,"SL") -> 0 | AP4: =COUNTIF(D4:AI4,"AL") -> 0 | AQ4: =COUNTIF(D4:AI4,"ML") -> 0 | AR4: =COUNTIF(D4:AI4,"PL") -> 0 | AS4: =COUNTIF(D4:AI4,"WFH") -> 0 | AT4: =COUNTIF(D4:AI4,"NH") -> 0 | AU4: =SUM(AJ4:AT4) -> 0
B5: Joseph Opolot | C5: VUEMP002 | AJ5: =COUNTIF(C5:AI5,"P") -> 0 | AK5: =COUNTIF(D5:AI5,"A") -> 0 | AL5: =COUNTIF(D5:AI5,"H") -> 0 | AM5: =COUNTIF(D5:AI5,"TR") -> 0 | AN5: =COUNTIF(D5:AI5,"CL") -> 0 | AO5: =COUNTIF(D5:AI5,"SL") -> 0 | AP5: =COUNTIF(D5:AI5,"AL") -> 0 | AQ5: =COUNTIF(D5:AI5,"ML") -> 0 | AR5: =COUNTIF(D5:AI5,"PL") -> 0 | AS5: =COUNTIF(D5:AI5,"WFH") -> 0 | AT5: =COUNTIF(D5:AI5,"NH") -> 0 | AU5: =SUM(AJ5:AT5) -> 0
B6: Moses Ikwara | C6: VUEMP004 | AJ6: =COUNTIF(C6:AI6,"P") -> 0 | AK6: =COUNTIF(D6:AI6,"A") -> 0 | AL6: =COUNTIF(D6:AI6,"H") -> 0 | AM6: =COUNTIF(D6:AI6,"TR") -> 0 | AN6: =COUNTIF(D6:AI6,"CL") -> 0 | AO6: =COUNTIF(D6:AI6,"SL") -> 0 | AP6: =COUNTIF(D6:AI6,"AL") -> 0 | AQ6: =COUNTIF(D6:AI6,"ML") -> 0 | AR6: =COUNTIF(D6:AI6,"PL") -> 0 | AS6: =COUNTIF(D6:AI6,"WFH") -> 0 | AT6: =COUNTIF(D6:AI6,"NH") -> 0 | AU6: =SUM(AJ6:AT6) -> 0
B7: Hawa Sirikye | C7: VUEMP005 | AJ7: =COUNTIF(C7:AI7,"P") -> 0 | AK7: =COUNTIF(D7:AI7,"A") -> 0 | AL7: =COUNTIF(D7:AI7,"H") -> 0 | AM7: =COUNTIF(D7:AI7,"TR") -> 0 | AN7: =COUNTIF(D7:AI7,"CL") -> 0 | AO7: =COUNTIF(D7:AI7,"SL") -> 0 | AP7: =COUNTIF(D7:AI7,"AL") -> 0 | AQ7: =COUNTIF(D7:AI7,"ML") -> 0 | AR7: =COUNTIF(D7:AI7,"PL") -> 0 | AS7: =COUNTIF(D7:AI7,"WFH") -> 0 | AT7: =COUNTIF(D7:AI7,"NH") -> 0 | AU7: =SUM(AJ7:AT7) -> 0
B8: Aneesh Mathew | C8: VUEMP008 | AJ8: =COUNTIF(C8:AI8,"P") -> 0 | AK8: =COUNTIF(D8:AI8,"A") -> 0 | AL8: =COUNTIF(D8:AI8,"H") -> 0 | AM8: =COUNTIF(D8:AI8,"TR") -> 0 | AN8: =COUNTIF(D8:AI8,"CL") -> 0 | AO8: =COUNTIF(D8:AI8,"SL") -> 0 | AP8: =COUNTIF(D8:AI8,"AL") -> 0 | AQ8: =COUNTIF(D8:AI8,"ML") -> 0 | AR8: =COUNTIF(D8:AI8,"PL") -> 0 | AS8: =COUNTIF(D8:AI8,"WFH") -> 0 | AT8: =COUNTIF(D8:AI8,"NH") -> 0 | AU8: =SUM(AJ8:AT8) -> 0
